Workbook

Sheet Scoring
B1: LEAGUE SETTINGS & SCORING INPUTS
A2: INPUT YOUR LEAGUE SCORING HERE | I2: LEAGUE & ROSTER SETTINGS
A3: Setting: | B3: Points: | C3: DESCRIPTION | I3: #TEAMS: | J3: QB: | K3: RB: | L3: WR: | M3: TE: | N3: FLEX: | O3: BENCH: | P3: SUPERFLEX:
A4: PASSING | I4: 10 | J4: 1 | K4: 2 | L4: 3 | M4: 1 | N4: 0 | O4: 6 | P4: 0
A5: PassINCMP | B5: 0 | C5: Points Per Pass Incompletion (Use a Negative, Default is 0) | I5: ADVANCED SETTINGS
A6: PassCMP | B6: 0 | C6: Points Per Pass Completion (Default is 0) | I6: Snake/Auction | K6: Auction | L6: ESTIMATED KEEPER SAVINGS
A7: PassYDS | B7: 50 | C7: Passing Yards Per 1 Point (Default is 25) | I7: Budget: | K7: 200 | L7: Est. Total Saved (Auction Keepers) | P7: 0
A8: PassTDs | B8: 6 | C8: Points Per Passing Touchdown (Default is 4)
A9: INTS | B9: -2 | C9: Points Per Interception (Use a Negative, Default is -2)
A10: SACKS | B10: 0 | C10: Points Per Sack (Use a Negative, Default is 0)
A11: RUSHING
A12: RushATT | B12: 0 | C12: Points Per Rush Attempt (Default is 0)
A13: RushYDS | B13: 10 | C13: Rushing Yards Per 1 Point (Default is 10)
A14: RushTDS | B14: 6 | C14: Points Per Rushing Touchdown (Default is 6)
A15: RECEIVING
A16: RB PPR | B16: 0.5 | C16: RB Points Per Reception (Examples: 0 , .5 , 1)
A17: WR PPR | B17: 0.5 | C17: WR Points Per Reception (Examples: 0 , .5 , 1)
A18: TE PPR | B18: 0.5 | C18: TE Points Per Reception (Examples: 0 , .5 , 1)
A19: RecYDS | B19: 10 | C19: Receiving Yards Per 1 Point (Default is 10)
A20: RecTDS | B20: 6 | C20: Points Per Receiving Touchdown (Default is 6)
A21: OTHER:
A22: FL | B22: -2 | C22: Points Per Fumble Lost (Use a Negative, Default is -2)
A23: Pass1D | B23: 0 | C23: Points Per Passing 1st Down (Default is 0)
A24: Rush1D | B24: 0 | C24: Points Per Rushing 1st Down (Default is 0)
A25: Rec1D | B25: 0 | C25: Points Per Receiving 1st Down (Default is 0)
A28: 🔒 CALCULATED VALUES BELOW — DO NOT EDIT (used internally for VBD/Auction math)
A29: QBs: | B29: PassCMP | C29: PassYDS | D29: PassTDs | E29: INTS | F29: RushATT | G29: RushYDS | H29: RushTDS | I29: FL | J29: Pass1D | K29: Rush1D
A30: POINTS | B30: =B6 -> 0 | C30: =B7 -> 50 | D30: =B8 -> 6 | E30: =B9 -> -2 | F30: =B12 -> 0 | G30: =B13 -> 10 | H30: =B14 -> 6 | I30: =B22 -> -2 | J30: =B23 -> 0 | K30: =B24 -> 0
A31: RBs: | B31: RushATT | C31: RushYDS | D31: RushTDS | E31: PPR | F31: RecYDS | G31: RecTDS | H31: FL | I31: Rush1D | J31: Rec1D
A32: POINTS | B32: =B12 -> 0 | C32: =B13 -> 10 | D32: =B14 -> 6 | E32: =B16 -> 0.5 | F32: =B19 -> 10 | G32: =B20 -> 6 | H32: =B22 -> -2 | I32: =B24 -> 0 | J32: =B25 -> 0
A33: WRs: | B33: PPR | C33: RecYDS | D33: RecTDS | E33: RushATT | F33: RushYDS | G33: RushTDS | H33: FL | I33: Rush1D | J33: Rec1D
A34: POINTS | B34: =B17 -> 0.5 | C34: =B19 -> 10 | D34: =B20 -> 6 | E34: =B12 -> 0 | F34: =B13 -> 10 | G34: =B14 -> 6 | H34: =B22 -> -2 | I34: =B24 -> 0 | J34: =B25 -> 0
A35: TEs: | B35: PPR | C35: RecYDS | D35: RecTDS | E35: FL | F35: Rec1D
A36: POINTS | B36: =B18 -> 0.5 | C36: =B19 -> 10 | D36: =B20 -> 6 | E36: =B22 -> -2 | F36: =B25 -> 0
A38: Baseline Calcs
A39: #TEAMS: | B39: QB: | C39: RB: | D39: WR: | E39: TE: | F39: FLEX:
A40: =I4 -> 10 | B40: =J4+P4 -> 1 | C40: =K4 -> 2 | D40: =L4 -> 3 | E40: =M4 -> 1 | F40: =N4+I38 -> 0
A41: Roster | B41: =(J4+P4)*I4 -> 10 | C41: =K4*I4 -> 20 | D41: =L4*I4 -> 30 | E41: =M4*I4 -> 10 | F41: =N4*I4 -> 0
A42: Flex: | B42: 0 | C42: =FLEX!E1 -> 20 | D42: =FLEX!G1 -> 20 | E42: =FLEX!I1 -> 10
A43: Baselines: | B43: =ROUND(B41*1.2,) -> 12 | C43: =ROUND((C41+C42)*1.2,) -> 48 | D43: =ROUND((D41+D42)*1.3,) -> 65 | E43: =ROUND((E41+E42)*1.2,) -> 24
...

Sheet DraftSheet
B1: ="DRAFTSHEET - "&Scoring!I4&" Team - "&Scoring!B17&" PPR - "&Scoring!J4&"QB("&Aggregate!B1&")/"&Scoring!K4&"RB("&Aggregate!P1&")/"&Scoring!L4&"WR("&Aggregate!AD1&")/"&Scoring!M4&"TE("&Aggregate!AR1&")/"&Scoring!N4&"[RB/WR/TE]" -> DRAFTSHEET - 10 Team - 0.5 PPR - 1QB(12)/2RB(48)/3WR(65)/1TE(24)/0[RB/WR/TE] | AF1: PLAYER SEARCH
B2: ="Passing: "&Scoring!B8&" PPTD, "&ROUND(1/Scoring!B7,2)&" PPY, "&Scoring!B9&" Int | Rushing: "&Scoring!B14&" PPTD, "&ROUND(1/Scoring!B13,2)&" PPY | Receiving: "&Scoring!B20&" PPTD, "&ROUND(1/Scoring!B19,2)&" PPY, "&Scoring!B17&" PPR | Draft: use 'x' if drafted by someone else, 'o' if drafted by you | Updated: "&TEXT(TODAY(),"yyyy-mm-dd") -> Passing: 6 PPTD, 0.02 PPY, -2 Int | Rushing: 6 PPTD, 0.1 PPY | Receiving: 6 PPTD, 0.1 PPY, 0.5 PPR | Draft: use 'x' if drafted by someone else, 'o' if drafted by you | Updated: 2026-08-30 | AF2: TYPE NAME HERE: | AH2: =IF($AG$2="","",IFERROR(MATCH("*"&$AG$2&"*",C5:C44,0)+4,""))
B3: QUARTERBACK | L3: RUNNING BACK | V3: WIDE RECEIVER | AF3: Position: | AG3: =IF($AG$2="","",IF(AH2<>"","QB",IF(AH3<>"","RB",IF(AH4<>"","WR",IF(AH5<>"","TE","Not Found"))))) | AH3: =IF($AG$2="","",IFERROR(MATCH("*"&$AG$2&"*",M5:M84,0)+4,""))
B4: TIER | C4: NAME | D4: TM/BYE | E4: PTS | F4: VALUE | G4: PS | H4: ECR | I4: DRAFT | L4: TIER | M4: NAME | N4: TM/BYE | O4: PTS | P4: VALUE | Q4: PS | R4: ECR | S4: DRAFT | V4: TIER | W4: NAME | X4: TM/BYE | Y4: PTS | Z4: VALUE | AA4: PS | AB4: ECR | AC4: DRAFT | AF4: Tier: | AG4: {=IF($AG$2="","",IF(AH2<>"",INDEX(B:B,AH2),IF(AH3<>"",INDEX(L:L,AH3),IF(AH4<>"",INDEX(V:V,AH4),IF(AH5<>"",INDEX(B:B,AH5),"")))))} | AH4: =IF($AG$2="","",IFERROR(MATCH("*"&$AG$2&"*",W5:W84,0)+4,""))
B5: =IFERROR(VLOOKUP(DraftSheet!$C5,Aggregate!$B:$M,11,FALSE()),"") -> 1 | C5: =Aggregate!B3 -> Josh Allen | D5: =VLOOKUP(DraftSheet!$C5,Aggregate!B:M,4,FALSE()) -> BUF/7 | E5: =IFERROR(VLOOKUP(DraftSheet!$C5,Aggregate!$B:$M,8,FALSE()),"") -> 285.43762 | F5: =IF(Scoring!$K$6="Auction",IFERROR(VLOOKUP(DraftSheet!$C5,Aggregate!$B:$M,10,FALSE()),""),IFERROR(VLOOKUP(DraftSheet!$C5,Aggregate!$B:$M,9,FALSE()),"")) -> 17.714688 | G5: =SUMIFS($J6:J$44,$I6:I$44,"<>x",$I6:I$44,"<>o",$J6:J$44,">0")/Aggregate!$J$1 -> 0.66816192 | H5: {=IFERROR(INDEX(ECR!$K:$K,MATCH(DraftSheet!$C5,ECR!$C:$C,0)),"ND")} -> 26 | J5: =VLOOKUP(C5,Aggregate!B:J,9,FALSE()) -> 63.790813 | L5: =IFERROR(VLOOKUP(DraftSheet!$M5,Aggregate!$P:$AA,11,FALSE()),"") -> 1 | M5: =Aggregate!P3 -> Jahmyr Gibbs | N5: =VLOOKUP(DraftSheet!$M5,Aggregate!P:AA,4,FALSE()) -> DET/6 | O5: =IFERROR(VLOOKUP(DraftSheet!$M5,Aggregate!$P:$AA,8,FALSE()),"") -> 257.64662 | P5: =IF(Scoring!$K$6="Auction",IFERROR(VLOOKUP(DraftSheet!$M5,Aggregate!$P:$AA,10,FALSE()),""),IFERROR(VLOOKUP(DraftSheet!$M5,Aggregate!$P:$AA,9,FALSE()),"")) -> 47.969201 | Q5: =SUMIFS($T6:T$84,$S6:S$84,"<>x",$S6:S$84,"<>o",$T6:T$84,">0")/Aggregate!$X$1 -> 0.94423057 | R5: {=IFERROR(INDEX(ECR!$K:$K,MATCH(DraftSheet!$M5,ECR!$C:$C,0)),"ND")} -> 1 | T5: =VLOOKUP(M5,Aggregate!P:X,9,FALSE()) -> 179.25573 | V5: =IFERROR(VLOOKUP(DraftSheet!$W5,Aggregate!$AD:$AO,11,FALSE()),"") -> 1 | W5: =Aggregate!AD4 -> Puka Nacua | X5: =VLOOKUP(DraftSheet!$W5,Aggregate!AD:AO,4,FALSE()) -> LAR/11 | Y5: =IFERROR(VLOOKUP(DraftSheet!$W5,Aggregate!$AD:$AO,8,FALSE()),"") -> 236.31248 | Z5: =IF(Scoring!$K$6="Auction",IFERROR(VLOOKUP(DraftSheet!$W5,Aggregate!$AD:$AO,10,FALSE()),""),IFERROR(VLOOKUP(DraftSheet!$W5,Aggregate!$AD:$AO,9,FALSE()),"")) -> 41.559012 | AA5: =SUMIFS($AD6:AD$84,$AC6:AC$84,"<>x",$AC6:AC$84,"<>o",$AD6:AD$84,">0")/Aggregate!$AL$1 -> 0.94791663 | AB5: {=IFERROR(INDEX(ECR!$K:$K,MATCH(DraftSheet!$W5,ECR!$C:$C,0)),"ND")} -> 4 | AD5: =VLOOKUP(W5,Aggregate!AD:AL,9,FALSE()) -> 154.79155 | AF5: Name: | AG5: {=IF($AG$2="","",IF(AH2<>"",INDEX(C:C,AH2),IF(AH3<>"",INDEX(M:M,AH3),IF(AH4<>"",INDEX(W:W,AH4),IF(AH5<>"",INDEX(C:C,AH5),"")))))} | AH5: =IF($AG$2="","",IFERROR(MATCH("*"&$AG$2&"*",C48:C84,0)+47,""))
B6: =IFERROR(VLOOKUP(DraftSheet!$C6,Aggregate!$B:$M,11,FALSE()),"") -> 2 | C6: =Aggregate!B4 -> Lamar Jackson | D6: =VLOOKUP(DraftSheet!$C6,Aggregate!B:M,4,FALSE()) -> BAL/13 | E6: =IFERROR(VLOOKUP(DraftSheet!$C6,Aggregate!$B:$M,8,FALSE()),"") -> 253.12593 | F6: =IF(Scoring!$K$6="Auction",IFERROR(VLOOKUP(DraftSheet!$C6,Aggregate!$B:$M,10,FALSE()),""),IFERROR(VLOOKUP(DraftSheet!$C6,Aggregate!$B:$M,9,FALSE()),"")) -> 9.2482674 | G6: =SUMIFS($J7:J$44,$I7:I$44,"<>x",$I7:I$44,"<>o",$J7:J$44,">0")/Aggregate!$J$1 -> 0.50440838 | H6: {=IFERROR(INDEX(ECR!$K:$K,MATCH(DraftSheet!$C6,ECR!$C:$C,0)),"ND")} -> 37 | J6: =VLOOKUP(C6,Aggregate!B:J,9,FALSE()) -> 31.479122 | L6: =IFERROR(VLOOKUP(DraftSheet!$M6,Aggregate!$P:$AA,11,FALSE()),"") -> 1 | M6: =Aggregate!P4 -> Bijan Robinson | N6: =VLOOKUP(DraftSheet!$M6,Aggregate!P:AA,4,FALSE()) -> ATL/11 | O6: =IFERROR(VLOOKUP(DraftSheet!$M6,Aggregate!$P:$AA,8,FALSE()),"") -> 243.30456 | P6: =IF(Scoring!$K$6="Auction",IFERROR(VLOOKUP(DraftSheet!$M6,Aggregate!$P:$AA,10,FALSE()),""),IFERROR(VLOOKUP(DraftSheet!$M6,Aggregate!$P:$AA,9,FALSE()),"")) -> 44.211245 | Q6: =SUMIFS($T7:T$84,$S7:S$84,"<>x",$S7:S$84,"<>o",$T7:T$84,">0")/Aggregate!$X$1 -> 0.89292318 | R6: {=IFERROR(INDEX(ECR!$K:$K,MATCH(DraftSheet!$M6,ECR!$C:$C,0)),"ND")} -> 2 | T6: =VLOOKUP(M6,Aggregate!P:X,9,FALSE()) -> 164.91367 | V6: =IFERROR(VLOOKUP(DraftSheet!$W6,Aggregate!$AD:$AO,11,FALSE()),"") -> 1 | W6: =Aggregate!AD3 -> Ja'Marr Chase | X6: =VLOOKUP(DraftSheet!$W6,Aggregate!AD:AO,4,FALSE()) -> CIN/6 | Y6: =IFERROR(VLOOKUP(DraftSheet!$W6,Aggregate!$AD:$AO,8,FALSE()),"") -> 234.13723 | Z6: =IF(Scoring!$K$6="Auction",IFERROR(VLOOKUP(DraftSheet!$W6,Aggregate!$AD:$AO,10,FALSE()),""),IFERROR(VLOOKUP(DraftSheet!$W6,Aggregate!$AD:$AO,9,FALSE()),"")) -> 40.989047 | AA6: =SUMIFS($AD7:AD$84,$AC7:AC$84,"<>x",$AC7:AC$84,"<>o",$AD7:AD$84,">0")/Aggregate!$AL$1 -> 0.89814128 | AB6: {=IFERROR(INDEX(ECR!$K:$K,MATCH(DraftSheet!$W6,ECR!$C:$C,0)),"ND")} -> 3 | AD6: =VLOOKUP(W6,Aggregate!AD:AL,9,FALSE()) -> 152.6163 | AF6: TM/BYE: | AG6: {=IF($AG$2="","",IF(AH2<>"",INDEX(D:D,AH2),IF(AH3<>"",INDEX(N:N,AH3),IF(AH4<>"",INDEX(X:X,AH4),IF(AH5<>"",INDEX(D:D,AH5),"")))))}
B7: =IFERROR(VLOOKUP(DraftSheet!$C7,Aggregate!$B:$M,11,FALSE()),"") -> 2 | C7: =Aggregate!B5 -> Drake Maye | D7: =VLOOKUP(DraftSheet!$C7,Aggregate!B:M,4,FALSE()) -> NE/11 | E7: =IFERROR(VLOOKUP(DraftSheet!$C7,Aggregate!$B:$M,8,FALSE()),"") -> 241.33652 | F7: =IF(Scoring!$K$6="Auction",IFERROR(VLOOKUP(DraftSheet!$C7,Aggregate!$B:$M,10,FALSE()),""),IFERROR(VLOOKUP(DraftSheet!$C7,Aggregate!$B:$M,9,FALSE()),"")) -> 6.1591651 | G7: =SUMIFS($J8:J$44,$I8:I$44,"<>x",$I8:I$44,"<>o",$J8:J$44,">0")/Aggregate!$J$1 -> 0.40198304 | H7: {=IFERROR(INDEX(ECR!$K:$K,MATCH(DraftSheet!$C7,ECR!$C:$C,0)),"ND")} -> 45 | J7: =VLOOKUP(C7,Aggregate!B:J,9,FALSE()) -> 19.689709 | L7: =IFERROR(VLOOKUP(DraftSheet!$M7,Aggregate!$P:$AA,11,FALSE()),"") -> 2 | M7: =Aggregate!P5 -> Christian McCaffrey | N7: =VLOOKUP(DraftSheet!$M7,Aggregate!P:AA,4,FALSE()) -> SF/8 | O7: =IFERROR(VLOOKUP(DraftSheet!$M7,Aggregate!$P:$AA,8,FALSE()),"") -> 224.92676 | P7: =IF(Scoring!$K$6="Auction",IFERROR(VLOOKUP(DraftSheet!$M7,Aggregate!$P:$AA,10,FALSE()),""),IFERROR(VLOOKUP(DraftSheet!$M7,Aggregate!$P:$AA,9,FALSE()),"")) -> 39.395833 | Q7: =SUMIFS($T8:T$84,$S8:S$84,"<>x",$S8:S$84,"<>o",$T8:T$84,">0")/Aggregate!$X$1 -> 0.84733344 | R7: {=IFERROR(INDEX(ECR!$K:$K,MATCH(DraftSheet!$M7,ECR!$C:$C,0)),"ND")} -> 7 | T7: =VLOOKUP(M7,Aggregate!P:X,9,FALSE()) -> 146.53588 | V7: =IFERROR(VLOOKUP(DraftSheet!$W7,Aggregate!$AD:$AO,11,FALSE()),"") -> 1 | W7: =Aggregate!AD5 -> Jaxon Smith-Njigba | X7: =VLOOKUP(DraftSheet!$W7,Aggregate!AD:AO,4,FALSE()) -> SEA/11 | Y7: =IFERROR(VLOOKUP(DraftSheet!$W7,Aggregate!$AD:$AO,8,FALSE()),"") -> 228.34417 | Z7: =IF(Scoring!$K$6="Auction",IFERROR(VLOOKUP(DraftSheet!$W7,Aggregate!$AD:$AO,10,FALSE()),""),IFERROR(VLOOKUP(DraftSheet!$W7,Aggregate!$AD:$AO,9,FALSE()),"")) -> 39.47113 | AA7: =SUMIFS($AD8:AD$84,$AC8:AC$84,"<>x",$AC8:AC$84,"<>o",$AD8:AD$84,">0")/Aggregate!$AL$1 -> 0.85025532 | AB7: {=IFERROR(INDEX(ECR!$K:$K,MATCH(DraftSheet!$W7,ECR!$C:$C,0)),"ND")} -> 5 | AD7: =VLOOKUP(W7,Aggregate!AD:AL,9,FALSE()) -> 146.82324 | AF7: PTS: | AG7: {=IF($AG$2="","",IF(AH2<>"",INDEX(E:E,AH2),IF(AH3<>"",INDEX(O:O,AH3),IF(AH4<>"",INDEX(Y:Y,AH4),IF(AH5<>"",INDEX(E:E,AH5),"")))))}
B8: =IFERROR(VLOOKUP(DraftSheet!$C8,Aggregate!$B:$M,11,FALSE()),"") -> 3 | C8: =Aggregate!B7 -> Jayden Daniels | D8: =VLOOKUP(DraftSheet!$C8,Aggregate!B:M,4,FALSE()) -> WAS/7 | E8: =IFERROR(VLOOKUP(DraftSheet!$C8,Aggregate!$B:$M,8,FALSE()),"") -> 239.84478 | F8: =IF(Scoring!$K$6="Auction",IFERROR(VLOOKUP(DraftSheet!$C8,Aggregate!$B:$M,10,FALSE()),""),IFERROR(VLOOKUP(DraftSheet!$C8,Aggregate!$B:$M,9,FALSE()),"")) -> 5.768296 | G8: =SUMIFS($J9:J$44,$I9:I$44,"<>x",$I9:I$44,"<>o",$J9:J$44,">0")/Aggregate!$J$1 -> 0.30731766 | H8: {=IFERROR(INDEX(ECR!$K:$K,MATCH(DraftSheet!$C8,ECR!$C:$C,0)),"ND")} -> 60 | J8: =VLOOKUP(C8,Aggregate!B:J,9,FALSE()) -> 18.197976 | L8: =IFERROR(VLOOKUP(DraftSheet!$M8,Aggregate!$P:$AA,11,FALSE()),"") -> 2 | M8: =Aggregate!P6 -> Jonathan Taylor | N8: =VLOOKUP(DraftSheet!$M8,Aggregate!P:AA,4,FALSE()) -> IND/13 | O8: =IFERROR(VLOOKUP(DraftSheet!$M8,Aggregate!$P:$AA,8,FALSE()),"") -> 222.03426 | P8: =IF(Scoring!$K$6="Auction",IFERROR(VLOOKUP(DraftSheet!$M8,Aggregate!$P:$AA,10,FALSE()),""),IFERROR(VLOOKUP(DraftSheet!$M8,Aggregate!$P:$AA,9,FALSE()),"")) -> 38.63793 | Q8: =SUMIFS($T9:T$84,$S9:S$84,"<>x",$S9:S$84,"<>o",$T9:T$84,">0")/Aggregate!$X$1 -> 0.8026436 | R8: {=IFERROR(INDEX(ECR!$K:$K,MATCH(DraftSheet!$M8,ECR!$C:$C,0)),"ND")} -> 8 | T8: =VLOOKUP(M8,Aggregate!P:X,9,FALSE()) -> 143.64338 | V8: =IFERROR(VLOOKUP(DraftSheet!$W8,Aggregate!$AD:$AO,11,FALSE()),"") -> 1 | W8: =Aggregate!AD6 -> Amon-Ra St. Brown | X8: =VLOOKUP(DraftSheet!$W8,Aggregate!AD:AO,4,FALSE()) -> DET/6 | Y8: =IFERROR(VLOOKUP(DraftSheet!$W8,Aggregate!$AD:$AO,8,FALSE()),"") -> 218.04724 | Z8: =IF(Scoring!$K$6="Auction",IFERROR(VLOOKUP(DraftSheet!$W8,Aggregate!$AD:$AO,10,FALSE()),""),IFERROR(VLOOKUP(DraftSheet!$W8,Aggregate!$AD:$AO,9,FALSE()),"")) -> 36.773092 | AA8: =SUMIFS($AD9:AD$84,$AC9:AC$84,"<>x",$AC9:AC$84,"<>o",$AD9:AD$84,">0")/Aggregate!$AL$1 -> 0.80572768 | AB8: {=IFERROR(INDEX(ECR!$K:$K,MATCH(DraftSheet!$W8,ECR!$C:$C,0)),"ND")} -> 6 | AD8: =VLOOKUP(W8,Aggregate!AD:AL,9,FALSE()) -> 136.52631 | AF8: VALUE: | AG8: {=IF($AG$2="","",IF(AH2<>"",INDEX(F:F,AH2),IF(AH3<>"",INDEX(P:P,AH3),IF(AH4<>"",INDEX(Z:Z,AH4),IF(AH5<>"",INDEX(F:F,AH5),"")))))}
B9: =IFERROR(VLOOKUP(DraftSheet!$C9,Aggregate!$B:$M,11,FALSE()),"") -> 2 | C9: =Aggregate!B8 -> Jalen Hurts | D9: =VLOOKUP(DraftSheet!$C9,Aggregate!B:M,4,FALSE()) -> PHI/10 | E9: =IFERROR(VLOOKUP(DraftSheet!$C9,Aggregate!$B:$M,8,FALSE()),"") -> 243.38374 | F9: =IF(Scoring!$K$6="Auction",IFERROR(VLOOKUP(DraftSheet!$C9,Aggregate!$B:$M,10,FALSE()),""),IFERROR(VLOOKUP(DraftSheet!$C9,Aggregate!$B:$M,9,FALSE()),"")) -> 6.6955854 | G9: =SUMIFS($J10:J$44,$I10:I$44,"<>x",$I10:I$44,"<>o",$J10:J$44,">0")/Aggregate!$J$1 -> 0.19424273 | H9: {=IFERROR(INDEX(ECR!$K:$K,MATCH(DraftSheet!$C9,ECR!$C:$C,0)),"ND")} -> 63 | J9: =VLOOKUP(C9,Aggregate!B:J,9,FALSE()) -> 21.736932 | L9: =IFERROR(VLOOKUP(DraftSheet!$M9,Aggregate!$P:$AA,11,FALSE()),"") -> 3 | M9: =Aggregate!P10 -> De'Von Achane | N9: =VLOOKUP(DraftSheet!$M9,Aggregate!P:AA,4,FALSE()) -> MIA/6 | O9: =IFERROR(VLOOKUP(DraftSheet!$M9,Aggregate!$P:$AA,8,FALSE()),"") -> 197.73382 | P9: =IF(Scoring!$K$6="Auction",IFERROR(VLOOKUP(DraftSheet!$M9,Aggregate!$P:$AA,10,FALSE()),""),IFERROR(VLOOKUP(DraftSheet!$M9,Aggregate!$P:$AA,9,FALSE()),"")) -> 32.270645 | Q9: =SUMIFS($T10:T$84,$S10:S$84,"<>x",$S10:S$84,"<>o",$T10:T$84,">0")/Aggregate!$X$1 -> 0.76551403 | R9: {=IFERROR(INDEX(ECR!$K:$K,MATCH(DraftSheet!$M9,ECR!$C:$C,0)),"ND")} -> 16 | T9: =VLOOKUP(M9,Aggregate!P:X,9,FALSE()) -> 119.34293 | V9: =IFERROR(VLOOKUP(DraftSheet!$W9,Aggregate!$AD:$AO,11,FALSE()),"") -> 2 | W9: =Aggregate!AD8 -> Justin Jefferson | X9: =VLOOKUP(DraftSheet!$W9,Aggregate!AD:AO,4,FALSE()) -> MIN/6 | Y9: =IFERROR(VLOOKUP(DraftSheet!$W9,Aggregate!$AD:$AO,8,FALSE()),"") -> 185.23229 | Z9: =IF(Scoring!$K$6="Auction",IFERROR(VLOOKUP(DraftSheet!$W9,Aggregate!$AD:$AO,10,FALSE()),""),IFERROR(VLOOKUP(DraftSheet!$W9,Aggregate!$AD:$AO,9,FALSE()),"")) -> 28.174807 | AA9: =SUMIFS($AD10:AD$84,$AC10:AC$84,"<>x",$AC10:AC$84,"<>o",$AD10:AD$84,">0")/Aggregate!$AL$1 -> 0.77190253 | AB9: {=IFERROR(INDEX(ECR!$K:$K,MATCH(DraftSheet!$W9,ECR!$C:$C,0)),"ND")} -> 11 | AD9: =VLOOKUP(W9,Aggregate!AD:AL,9,FALSE()) -> 103.71136 | AF9: PS: | AG9: {=IF($AG$2="","",IF(AH2<>"",INDEX(G:G,AH2),IF(AH3<>"",INDEX(Q:Q,AH3),IF(AH4<>"",INDEX(AA:AA,AH4),IF(AH5<>"",INDEX(G:G,AH5),"")))))}
B10: =IFERROR(VLOOKUP(DraftSheet!$C10,Aggregate!$B:$M,11,FALSE()),"") -> 3 | C10: =Aggregate!B6 -> Joe Burrow | D10: =VLOOKUP(DraftSheet!$C10,Aggregate!B:M,4,FALSE()) -> CIN/6 | E10: =IFERROR(VLOOKUP(DraftSheet!$C10,Aggregate!$B:$M,8,FALSE()),"") -> 239.37106 | F10: =IF(Scoring!$K$6="Auction",IFERROR(VLOOKUP(DraftSheet!$C10,Aggregate!$B:$M,10,FALSE()),""),IFERROR(VLOOKUP(DraftSheet!$C10,Aggregate!$B:$M,9,FALSE()),"")) -> 5.6441702 | G10: =SUMIFS($J11:J$44,$I11:I$44,"<>x",$I11:I$44,"<>o",$J11:J$44,">0")/Aggregate!$J$1 -> 0.10204164 | H10: {=IFERROR(INDEX(ECR!$K:$K,MATCH(DraftSheet!$C10,ECR!$C:$C,0)),"ND")} -> 50 | J10: =VLOOKUP(C10,Aggregate!B:J,9,FALSE()) -> 17.724256 | L10: =IFERROR(VLOOKUP(DraftSheet!$M10,Aggregate!$P:$AA,11,FALSE()),"") -> 3 | M10: =Aggregate!P12 -> Derrick Henry | N10: =VLOOKUP(DraftSheet!$M10,Aggregate!P:AA,4,FALSE()) -> BAL/13 | O10: =IFERROR(VLOOKUP(DraftSheet!$M10,Aggregate!$P:$AA,8,FALSE()),"") -> 196.88118 | P10: =IF(Scoring!$K$6="Auction",IFERROR(VLOOKUP(DraftSheet!$M10,Aggregate!$P:$AA,10,FALSE()),""),IFERROR(VLOOKUP(DraftSheet!$M10,Aggregate!$P:$AA,9,FALSE()),"")) -> 32.047231 | Q10: =SUMIFS($T11:T$84,$S11:S$84,"<>x",$S11:S$84,"<>o",$T11:T$84,">0")/Aggregate!$X$1 -> 0.72864973 | R10: {=IFERROR(INDEX(ECR!$K:$K,MATCH(DraftSheet!$M10,ECR!$C:$C,0)),"ND")} -> 20 | T10: =VLOOKUP(M10,Aggregate!P:X,9,FALSE()) -> 118.49029 | V10: =IFERROR(VLOOKUP(DraftSheet!$W10,Aggregate!$AD:$AO,11,FALSE()),"") -> 2 | W10: =Aggregate!AD7 -> CeeDee Lamb | X10: =VLOOKUP(DraftSheet!$W10,Aggregate!AD:AO,4,FALSE()) -> DAL/14 | Y10: =IFERROR(VLOOKUP(DraftSheet!$W10,Aggregate!$AD:$AO,8,FALSE()),"") -> 184.0414 | Z10: =IF(Scoring!$K$6="Auction",IFERROR(VLOOKUP(DraftSheet!$W10,Aggregate!$AD:$AO,10,FALSE()),""),IFERROR(VLOOKUP(DraftSheet!$W10,Aggregate!$AD:$AO,9,FALSE()),"")) -> 27.862767 | AA10: =SUMIFS($AD11:AD$84,$AC11:AC$84,"<>x",$AC11:AC$84,"<>o",$AD11:AD$84,">0")/Aggregate!$AL$1 -> 0.73846579 | AB10: {=IFERROR(INDEX(ECR!$K:$K,MATCH(DraftSheet!$W10,ECR!$C:$C,0)),"ND")} -> 9 | AD10: =VLOOKUP(W10,Aggregate!AD:AL,9,FALSE()) -> 102.52048 | AF10: ECR: | AG10: {=IF($AG$2="","",IF(AH2<>"",INDEX(H:H,AH2),IF(AH3<>"",INDEX(R:R,AH3),IF(AH4<>"",INDEX(AB:AB,AH4),IF(AH5<>"",INDEX(H:H,AH5),"")))))}
B11: =IFERROR(VLOOKUP(DraftSheet!$C11,Aggregate!$B:$M,11,FALSE()),"") -> 4 | C11: =Aggregate!B11 -> Trevor Lawrence | D11: =VLOOKUP(DraftSheet!$C11,Aggregate!B:M,4,FALSE()) -> JAC/7 | E11: =IFERROR(VLOOKUP(DraftSheet!$C11,Aggregate!$B:$M,8,FALSE()),"") -> 227.08694 | F11: =IF(Scoring!$K$6="Auction",IFERROR(VLOOKUP(DraftSheet!$C11,Aggregate!$B:$M,10,FALSE()),""),IFERROR(VLOOKUP(DraftSheet!$C11,Aggregate!$B:$M,9,FALSE()),"")) -> 2.4254426 | G11: =SUMIFS($J12:J$44,$I12:I$44,"<>x",$I12:I$44,"<>o",$J12:J$44,">0")/Aggregate!$J$1 -> 0.073742205 | H11: {=IFERROR(INDEX(ECR!$K:$K,MATCH(DraftSheet!$C11,ECR!$C:$C,0)),"ND")} -> 75 | J11: =VLOOKUP(C11,Aggregate!B:J,9,FALSE()) -> 5.4401341 | L11: =IFERROR(VLOOKUP(DraftSheet!$M11,Aggregate!$P:$AA,11,FALSE()),"") -> 3 | M11: =Aggregate!P7 -> James Cook III | N11: =VLOOKUP(DraftSheet!$M11,Aggregate!P:AA,4,FALSE()) -> BUF/7 | O11: =IFERROR(VLOOKUP(DraftSheet!$M11,Aggregate!$P:$AA,8,FALSE()),"") -> 195.69397 | P11: =IF(Scoring!$K$6="Auction",IFERROR(VLOOKUP(DraftSheet!$M11,Aggregate!$P:$AA,10,FALSE()),""),IFERROR(VLOOKUP(DraftSheet!$M11,Aggregate!$P:$AA,9,FALSE()),"")) -> 31.736156 | Q11: =SUMIFS($T12:T$84,$S12:S$84,"<>x",$S12:S$84,"<>o",$T12:T$84,">0")/Aggregate!$X$1 -> 0.69215479 | R11: {=IFERROR(INDEX(ECR!$K:$K,MATCH(DraftSheet!$M11,ECR!$C:$C,0)),"ND")} -> 10 | T11: =VLOOKUP(M11,Aggregate!P:X,9,FALSE()) -> 117.30308 | V11: =IFERROR(VLOOKUP(DraftSheet!$W11,Aggregate!$AD:$AO,11,FALSE()),"") -> 2 | W11: =Aggregate!AD9 -> Drake London | X11: =VLOOKUP(DraftSheet!$W11,Aggregate!AD:AO,4,FALSE()) -> ATL/11 | Y11: =IFERROR(VLOOKUP(DraftSheet!$W11,Aggregate!$AD:$AO,8,FALSE()),"") -> 181.26158 | Z11: =IF(Scoring!$K$6="Auction",IFERROR(VLOOKUP(DraftSheet!$W11,Aggregate!$AD:$AO,10,FALSE()),""),IFERROR(VLOOKUP(DraftSheet!$W11,Aggregate!$AD:$AO,9,FALSE()),"")) -> 27.134388 | AA11: =SUMIFS($AD12:AD$84,$AC12:AC$84,"<>x",$AC12:AC$84,"<>o",$AD12:AD$84,">0")/Aggregate!$AL$1 -> 0.70593567 | AB11: {=IFERROR(INDEX(ECR!$K:$K,MATCH(DraftSheet!$W11,ECR!$C:$C,0)),"ND")} -> 13 | AD11: =VLOOKUP(W11,Aggregate!AD:AL,9,FALSE()) -> 99.740655 | AF11: Drafted?: | AG11: {=IF($AG$2="","",IF(AH2<>"",IF(INDEX(I:I,AH2)="","Available",INDEX(I:I,AH2)),IF(AH3<>"",IF(INDEX(S:S,AH3)="","Available",INDEX(S:S,AH3)),IF(AH4<>"",IF(INDEX(AC:AC,AH4)="","Available",INDEX(AC:AC,AH4)),IF(AH5<>"",IF(INDEX(I:I,AH5)="","Available",INDEX(I:I,AH5)),"")))))}
B12: =IFERROR(VLOOKUP(DraftSheet!$C12,Aggregate!$B:$M,11,FALSE()),"") -> 4 | C12: =Aggregate!B14 -> Jaxson Dart | D12: =VLOOKUP(DraftSheet!$C12,Aggregate!B:M,4,FALSE()) -> NYG/8 | E12: =IFERROR(VLOOKUP(DraftSheet!$C12,Aggregate!$B:$M,8,FALSE()),"") -> 224.79842 | F12: =IF(Scoring!$K$6="Auction",IFERROR(VLOOKUP(DraftSheet!$C12,Aggregate!$B:$M,10,FALSE()),""),IFERROR(VLOOKUP(DraftSheet!$C12,Aggregate!$B:$M,9,FALSE()),"")) -> 1.8257977 | G12: =SUMIFS($J13:J$44,$I13:I$44,"<>x",$I13:I$44,"<>o",$J13:J$44,">0")/Aggregate!$J$1 -> 0.057347574 | H12: {=IFERROR(INDEX(ECR!$K:$K,MATCH(DraftSheet!$C12,ECR!$C:$C,0)),"ND")} -> 98 | J12: =VLOOKUP(C12,Aggregate!B:J,9,FALSE()) -> 3.1516179 | L12: =IFERROR(VLOOKUP(DraftSheet!$M12,Aggregate!$P:$AA,11,FALSE()),"") -> 3 | M12: =Aggregate!P8 -> Chase Brown | N12: =VLOOKUP(DraftSheet!$M12,Aggregate!P:AA,4,FALSE()) -> CIN/6 | O12: =IFERROR(VLOOKUP(DraftSheet!$M12,Aggregate!$P:$AA,8,FALSE()),"") -> 191.45368 | P12: =IF(Scoring!$K$6="Auction",IFERROR(VLOOKUP(DraftSheet!$M12,Aggregate!$P:$AA,10,FALSE()),""),IFERROR(VLOOKUP(DraftSheet!$M12,Aggregate!$P:$AA,9,FALSE()),"")) -> 30.625099 | Q12: =SUMIFS($T13:T$84,$S13:S$84,"<>x",$S13:S$84,"<>o",$T13:T$84,">0")/Aggregate!$X$1 -> 0.65697908 | R12: {=IFERROR(INDEX(ECR!$K:$K,MATCH(DraftSheet!$M12,ECR!$C:$C,0)),"ND")} -> 12 | T12: =VLOOKUP(M12,Aggregate!P:X,9,FALSE()) -> 113.06279 | V12: =IFERROR(VLOOKUP(DraftSheet!$W12,Aggregate!$AD:$AO,11,FALSE()),"") -> 2 | W12: =Aggregate!AD10 -> A.J. Brown | X12: =VLOOKUP(DraftSheet!$W12,Aggregate!AD:AO,4,FALSE()) -> NE/11 | Y12: =IFERROR(VLOOKUP(DraftSheet!$W12,Aggregate!$AD:$AO,8,FALSE()),"") -> 176.07863 | Z12: =IF(Scoring!$K$6="Auction",IFERROR(VLOOKUP(DraftSheet!$W12,Aggregate!$AD:$AO,10,FALSE()),""),IFERROR(VLOOKUP(DraftSheet!$W12,Aggregate!$AD:$AO,9,FALSE()),"")) -> 25.776334 | AA12: =SUMIFS($AD13:AD$84,$AC13:AC$84,"<>x",$AC13:AC$84,"<>o",$AD13:AD$84,">0")/Aggregate!$AL$1 -> 0.67509596 | AB12: {=IFERROR(INDEX(ECR!$K:$K,MATCH(DraftSheet!$W12,ECR!$C:$C,0)),"ND")} -> 15 | AD12: =VLOOKUP(W12,Aggregate!AD:AL,9,FALSE()) -> 94.557703
B13: =IFERROR(VLOOKUP(DraftSheet!$C13,Aggregate!$B:$M,11,FALSE()),"") -> 4 | C13: =Aggregate!B13 -> Brock Purdy | D13: =VLOOKUP(DraftSheet!$C13,Aggregate!B:M,4,FALSE()) -> SF/8 | E13: =IFERROR(VLOOKUP(DraftSheet!$C13,Aggregate!$B:$M,8,FALSE()),"") -> 221.64681 | F13: =IF(Scoring!$K$6="Auction",IFERROR(VLOOKUP(DraftSheet!$C13,Aggregate!$B:$M,10,FALSE()),""),IFERROR(VLOOKUP(DraftSheet!$C13,Aggregate!$B:$M,9,FALSE()),"")) -> 1 | G13: =SUMIFS($J14:J$44,$I14:I$44,"<>x",$I14:I$44,"<>o",$J14:J$44,">0")/Aggregate!$J$1 -> 0.057347574 | H13: {=IFERROR(INDEX(ECR!$K:$K,MATCH(DraftSheet!$C13,ECR!$C:$C,0)),"ND")} -> 91 | J13: =VLOOKUP(C13,Aggregate!B:J,9,FALSE()) -> 0 | L13: =IFERROR(VLOOKUP(DraftSheet!$M13,Aggregate!$P:$AA,11,FALSE()),"") -> 3 | M13: =Aggregate!P9 -> Saquon Barkley | N13: =VLOOKUP(DraftSheet!$M13,Aggregate!P:AA,4,FALSE()) -> PHI/10 | O13: =IFERROR(VLOOKUP(DraftSheet!$M13,Aggregate!$P:$AA,8,FALSE()),"") -> 188.48853 | P13: =IF(Scoring!$K$6="Auction",IFERROR(VLOOKUP(DraftSheet!$M13,Aggregate!$P:$AA,10,FALSE()),""),IFERROR(VLOOKUP(DraftSheet!$M13,Aggregate!$P:$AA,9,FALSE()),"")) -> 29.848161 | Q13: =SUMIFS($T14:T$84,$S14:S$84,"<>x",$S14:S$84,"<>o",$T14:T$84,">0")/Aggregate!$X$1 -> 0.62272588 | R13: {=IFERROR(INDEX(ECR!$K:$K,MATCH(DraftSheet!$M13,ECR!$C:$C,0)),"ND")} -> 14 | T13: =VLOOKUP(M13,Aggregate!P:X,9,FALSE()) -> 110.09764 | V13: =IFERROR(VLOOKUP(DraftSheet!$W13,Aggregate!$AD:$AO,11,FALSE()),"") -> 2 | W13: =Aggregate!AD15 -> Rashee Rice | X13: =VLOOKUP(DraftSheet!$W13,Aggregate!AD:AO,4,FALSE()) -> KC/5 | Y13: =IFERROR(VLOOKUP(DraftSheet!$W13,Aggregate!$AD:$AO,8,FALSE()),"") -> 174.72545 | Z13: =IF(Scoring!$K$6="Auction",IFERROR(VLOOKUP(DraftSheet!$W13,Aggregate!$AD:$AO,10,FALSE()),""),IFERROR(VLOOKUP(DraftSheet!$W13,Aggregate!$AD:$AO,9,FALSE()),"")) -> 25.421768 | AA13: =SUMIFS($AD14:AD$84,$AC14:AC$84,"<>x",$AC14:AC$84,"<>o",$AD14:AD$84,">0")/Aggregate!$AL$1 -> 0.64469759 | AB13: {=IFERROR(INDEX(ECR!$K:$K,MATCH(DraftSheet!$W13,ECR!$C:$C,0)),"ND")} -> 29 | AD13: =VLOOKUP(W13,Aggregate!AD:AL,9,FALSE()) -> 93.204521
B14: =IFERROR(VLOOKUP(DraftSheet!$C14,Aggregate!$B:$M,11,FALSE()),"") -> 4 | C14: =Aggregate!B12 -> Dak Prescott | D14: =VLOOKUP(DraftSheet!$C14,Aggregate!B:M,4,FALSE()) -> DAL/14 | E14: =IFERROR(VLOOKUP(DraftSheet!$C14,Aggregate!$B:$M,8,FALSE()),"") -> 226.10296 | F14: =IF(Scoring!$K$6="Auction",IFERROR(VLOOKUP(DraftSheet!$C14,Aggregate!$B:$M,10,FALSE()),""),IFERROR(VLOOKUP(DraftSheet!$C14,Aggregate!$B:$M,9,FALSE()),"")) -> 2.167618 | G14: =SUMIFS($J15:J$44,$I15:I$44,"<>x",$I15:I$44,"<>o",$J15:J$44,">0")/Aggregate!$J$1 -> 0.034166757 | H14: {=IFERROR(INDEX(ECR!$K:$K,MATCH(DraftSheet!$C14,ECR!$C:$C,0)),"ND")} -> 77 | J14: =VLOOKUP(C14,Aggregate!B:J,9,FALSE()) -> 4.4561587 | L14: =IFERROR(VLOOKUP(DraftSheet!$M14,Aggregate!$P:$AA,11,FALSE()),"") -> 3 | M14: =Aggregate!P13 -> Kenneth Walker III | N14: =VLOOKUP(DraftSheet!$M14,Aggregate!P:AA,4,FALSE()) -> KC/5 | O14: =IFERROR(VLOOKUP(DraftSheet!$M14,Aggregate!$P:$AA,8,FALSE()),"") -> 178.87723 | P14: =IF(Scoring!$K$6="Auction",IFERROR(VLOOKUP(DraftSheet!$M14,Aggregate!$P:$AA,10,FALSE()),""),IFERROR(VLOOKUP(DraftSheet!$M14,Aggregate!$P:$AA,9,FALSE()),"")) -> 27.329775 | Q14: =SUMIFS($T15:T$84,$S15:S$84,"<>x",$S15:S$84,"<>o",$T15:T$84,">0")/Aggregate!$X$1 -> 0.59146291 | R14: {=IFERROR(INDEX(ECR!$K:$K,MATCH(DraftSheet!$M14,ECR!$C:$C,0)),"ND")} -> 21 | T14: =VLOOKUP(M14,Aggregate!P:X,9,FALSE()) -> 100.48634 | V14: =IFERROR(VLOOKUP(DraftSheet!$W14,Aggregate!$AD:$AO,11,FALSE()),"") -> 2 | W14: =Aggregate!AD12 -> George Pickens | X14: =VLOOKUP(DraftSheet!$W14,Aggregate!AD:AO,4,FALSE()) -> DAL/14 | Y14: =IFERROR(VLOOKUP(DraftSheet!$W14,Aggregate!$AD:$AO,8,FALSE()),"") -> 173.13933 | Z14: =IF(Scoring!$K$6="Auction",IFERROR(VLOOKUP(DraftSheet!$W14,Aggregate!$AD:$AO,10,FALSE()),""),IFERROR(VLOOKUP(DraftSheet!$W14,Aggregate!$AD:$AO,9,FALSE()),"")) -> 25.006168 | AA14: =SUMIFS($AD15:AD$84,$AC15:AC$84,"<>x",$AC15:AC$84,"<>o",$AD15:AD$84,">0")/Aggregate!$AL$1 -> 0.61481653 | AB14: {=IFERROR(INDEX(ECR!$K:$K,MATCH(DraftSheet!$W14,ECR!$C:$C,0)),"ND")} -> 23 | AD14: =VLOOKUP(W14,Aggregate!AD:AL,9,FALSE()) -> 91.618401
B15: =IFERROR(VLOOKUP(DraftSheet!$C15,Aggregate!$B:$M,11,FALSE()),"") -> 4 | C15: =Aggregate!B9 -> Caleb Williams | D15: =VLOOKUP(DraftSheet!$C15,Aggregate!B:M,4,FALSE()) -> CHI/10 | E15: =IFERROR(VLOOKUP(DraftSheet!$C15,Aggregate!$B:$M,8,FALSE()),"") -> 227.06499 | F15: =IF(Scoring!$K$6="Auction",IFERROR(VLOOKUP(DraftSheet!$C15,Aggregate!$B:$M,10,FALSE()),""),IFERROR(VLOOKUP(DraftSheet!$C15,Aggregate!$B:$M,9,FALSE()),"")) -> 2.4196901 | G15: =SUMIFS($J16:J$44,$I16:I$44,"<>x",$I16:I$44,"<>o",$J16:J$44,">0")/Aggregate!$J$1 -> 0.005981532 | H15: {=IFERROR(INDEX(ECR!$K:$K,MATCH(DraftSheet!$C15,ECR!$C:$C,0)),"ND")} -> 67 | J15: =VLOOKUP(C15,Aggregate!B:J,9,FALSE()) -> 5.4181799 | L15: =IFERROR(VLOOKUP(DraftSheet!$M15,Aggregate!$P:$AA,11,FALSE()),"") -> 3 | M15: =Aggregate!P14 -> Ashton Jeanty | N15: =VLOOKUP(DraftSheet!$M15,Aggregate!P:AA,4,FALSE()) -> LV/13 | O15: =IFERROR(VLOOKUP(DraftSheet!$M15,Aggregate!$P:$AA,8,FALSE()),"") -> 178.21088 | P15: =IF(Scoring!$K$6="Auction",IFERROR(VLOOKUP(DraftSheet!$M15,Aggregate!$P:$AA,10,FALSE()),""),IFERROR(VLOOKUP(DraftSheet!$M15,Aggregate!$P:$AA,9,FALSE()),"")) -> 27.155177 | Q15: =SUMIFS($T16:T$84,$S16:S$84,"<>x",$S16:S$84,"<>o",$T16:T$84,">0")/Aggregate!$X$1 -> 0.56040725 | R15: {=IFERROR(INDEX(ECR!$K:$K,MATCH(DraftSheet!$M15,ECR!$C:$C,0)),"ND")} -> 22 | T15: =VLOOKUP(M15,Aggregate!P:X,9,FALSE()) -> 99.819993 | V15: =IFERROR(VLOOKUP(DraftSheet!$W15,Aggregate!$AD:$AO,11,FALSE()),"") -> 2 | W15: =Aggregate!AD13 -> Chris Olave | X15: =VLOOKUP(DraftSheet!$W15,Aggregate!AD:AO,4,FALSE()) -> NO/8 | Y15: =IFERROR(VLOOKUP(DraftSheet!$W15,Aggregate!$AD:$AO,8,FALSE()),"") -> 172.66006 | Z15: =IF(Scoring!$K$6="Auction",IFERROR(VLOOKUP(DraftSheet!$W15,Aggregate!$AD:$AO,10,FALSE()),""),IFERROR(VLOOKUP(DraftSheet!$W15,Aggregate!$AD:$AO,9,FALSE()),"")) -> 24.880588 | AA15: =SUMIFS($AD16:AD$84,$AC16:AC$84,"<>x",$AC16:AC$84,"<>o",$AD16:AD$84,">0")/Aggregate!$AL$1 -> 0.58509177 | AB15: {=IFERROR(INDEX(ECR!$K:$K,MATCH(DraftSheet!$W15,ECR!$C:$C,0)),"ND")} -> 24 | AD15: =VLOOKUP(W15,Aggregate!AD:AL,9,FALSE()) -> 91.139134
B16: =IFERROR(VLOOKUP(DraftSheet!$C16,Aggregate!$B:$M,11,FALSE()),"") -> 4 | C16: =Aggregate!B10 -> Justin Herbert | D16: =VLOOKUP(DraftSheet!$C16,Aggregate!B:M,4,FALSE()) -> LAC/7 | E16: =IFERROR(VLOOKUP(DraftSheet!$C16,Aggregate!$B:$M,8,FALSE()),"") -> 222.79666 | F16: =IF(Scoring!$K$6="Auction",IFERROR(VLOOKUP(DraftSheet!$C16,Aggregate!$B:$M,10,FALSE()),""),IFERROR(VLOOKUP(DraftSheet!$C16,Aggregate!$B:$M,9,FALSE()),"")) -> 1.3012898 | G16: =SUMIFS($J17:J$44,$I17:I$44,"<>x",$I17:I$44,"<>o",$J17:J$44,">0")/Aggregate!$J$1 -> 0 | H16: {=IFERROR(INDEX(ECR!$K:$K,MATCH(DraftSheet!$C16,ECR!$C:$C,0)),"ND")} -> 70 | J16: =VLOOKUP(C16,Aggregate!B:J,9,FALSE()) -> 1.1498584 | L16: =IFERROR(VLOOKUP(DraftSheet!$M16,Aggregate!$P:$AA,11,FALSE()),"") -> 3 | M16: =Aggregate!P19 -> Jeremiyah Love | N16: =VLOOKUP(DraftSheet!$M16,Aggregate!P:AA,4,FALSE()) -> ARI/14 | O16: =IFERROR(VLOOKUP(DraftSheet!$M16,Aggregate!$P:$AA,8,FALSE()),"") -> 176.69801 | P16: =IF(Scoring!$K$6="Auction",IFERROR(VLOOKUP(DraftSheet!$M16,Aggregate!$P:$AA,10,FALSE()),""),IFERROR(VLOOKUP(DraftSheet!$M16,Aggregate!$P:$AA,9,FALSE()),"")) -> 26.758768 | Q16: =SUMIFS($T17:T$84,$S17:S$84,"<>x",$S17:S$84,"<>o",$T17:T$84,">0")/Aggregate!$X$1 -> 0.52982227 | R16: {=IFERROR(INDEX(ECR!$K:$K,MATCH(DraftSheet!$M16,ECR!$C:$C,0)),"ND")} -> 44 | T16: =VLOOKUP(M16,Aggregate!P:X,9,FALSE()) -> 98.307118 | V16: =IFERROR(VLOOKUP(DraftSheet!$W16,Aggregate!$AD:$AO,11,FALSE()),"") -> 2 | W16: =Aggregate!AD11 -> Nico Collins | X16: =VLOOKUP(DraftSheet!$W16,Aggregate!AD:AO,4,FALSE()) -> HOU/8 | Y16: =IFERROR(VLOOKUP(DraftSheet!$W16,Aggregate!$AD:$AO,8,FALSE()),"") -> 170.2458 | Z16: =IF(Scoring!$K$6="Auction",IFERROR(VLOOKUP(DraftSheet!$W16,Aggregate!$AD:$AO,10,FALSE()),""),IFERROR(VLOOKUP(DraftSheet!$W16,Aggregate!$AD:$AO,9,FALSE()),"")) -> 24.247995 | AA16: =SUMIFS($AD17:AD$84,$AC17:AC$84,"<>x",$AC17:AC$84,"<>o",$AD17:AD$84,">0")/Aggregate!$AL$1 -> 0.55615443 | AB16: {=IFERROR(INDEX(ECR!$K:$K,MATCH(DraftSheet!$W16,ECR!$C:$C,0)),"ND")} -> 17 | AD16: =VLOOKUP(W16,Aggregate!AD:AL,9,FALSE()) -> 88.724871
B17: =IFERROR(VLOOKUP(DraftSheet!$C17,Aggregate!$B:$M,11,FALSE()),"") -> 4 | C17: =Aggregate!B16 -> Patrick Mahomes II | D17: =VLOOKUP(DraftSheet!$C17,Aggregate!B:M,4,FALSE()) -> KC/5 | E17: =IFERROR(VLOOKUP(DraftSheet!$C17,Aggregate!$B:$M,8,FALSE()),"") -> 221.32934 | F17: =IF(Scoring!$K$6="Auction",IFERROR(VLOOKUP(DraftSheet!$C17,Aggregate!$B:$M,10,FALSE()),""),IFERROR(VLOOKUP(DraftSheet!$C17,Aggregate!$B:$M,9,FALSE()),"")) -> 1 | G17: =SUMIFS($J18:J$44,$I18:I$44,"<>x",$I18:I$44,"<>o",$J18:J$44,">0")/Aggregate!$J$1 -> 0 | H17: {=IFERROR(INDEX(ECR!$K:$K,MATCH(DraftSheet!$C17,ECR!$C:$C,0)),"ND")} -> 104 | J17: =VLOOKUP(C17,Aggregate!B:J,9,FALSE()) -> -0.31746503 | L17: =IFERROR(VLOOKUP(DraftSheet!$M17,Aggregate!$P:$AA,11,FALSE()),"") -> 3 | M17: =Aggregate!P11 -> Omarion Hampton | N17: =VLOOKUP(DraftSheet!$M17,Aggregate!P:AA,4,FALSE()) -> LAC/7 | O17: =IFERROR(VLOOKUP(DraftSheet!$M17,Aggregate!$P:$AA,8,FALSE()),"") -> 176.54382 | P17: =IF(Scoring!$K$6="Auction",IFERROR(VLOOKUP(DraftSheet!$M17,Aggregate!$P:$AA,10,FALSE()),""),IFERROR(VLOOKUP(DraftSheet!$M17,Aggregate!$P:$AA,9,FALSE()),"")) -> 26.718369 | Q17: =SUMIFS($T18:T$84,$S18:S$84,"<>x",$S18:S$84,"<>o",$T18:T$84,">0")/Aggregate!$X$1 -> 0.49928526 | R17: {=IFERROR(INDEX(ECR!$K:$K,MATCH(DraftSheet!$M17,ECR!$C:$C,0)),"ND")} -> 19 | T17: =VLOOKUP(M17,Aggregate!P:X,9,FALSE()) -> 98.152934 | V17: =IFERROR(VLOOKUP(DraftSheet!$W17,Aggregate!$AD:$AO,11,FALSE()),"") -> 2 | W17: =Aggregate!AD14 -> Malik Nabers | X17: =VLOOKUP(DraftSheet!$W17,Aggregate!AD:AO,4,FALSE()) -> NYG/8 | Y17: =IFERROR(VLOOKUP(DraftSheet!$W17,Aggregate!$AD:$AO,8,FALSE()),"") -> 163.70708 | Z17: =IF(Scoring!$K$6="Auction",IFERROR(VLOOKUP(DraftSheet!$W17,Aggregate!$AD:$AO,10,FALSE()),""),IFERROR(VLOOKUP(DraftSheet!$W17,Aggregate!$AD:$AO,9,FALSE()),"")) -> 22.534697 | AA17: =SUMIFS($AD18:AD$84,$AC18:AC$84,"<>x",$AC18:AC$84,"<>o",$AD18:AD$84,">0")/Aggregate!$AL$1 -> 0.52934966 | AB17: {=IFERROR(INDEX(ECR!$K:$K,MATCH(DraftSheet!$W17,ECR!$C:$C,0)),"ND")} -> 28 | AD17: =VLOOKUP(W17,Aggregate!AD:AL,9,FALSE()) -> 82.18615
B18: =IFERROR(VLOOKUP(DraftSheet!$C18,Aggregate!$B:$M,11,FALSE()),"") -> 4 | C18: =Aggregate!B15 -> Bo Nix | D18: =VLOOKUP(DraftSheet!$C18,Aggregate!B:M,4,FALSE()) -> DEN/10 | E18: =IFERROR(VLOOKUP(DraftSheet!$C18,Aggregate!$B:$M,8,FALSE()),"") -> 217.49639 | F18: =IF(Scoring!$K$6="Auction",IFERROR(VLOOKUP(DraftSheet!$C18,Aggregate!$B:$M,10,FALSE()),""),IFERROR(VLOOKUP(DraftSheet!$C18,Aggregate!$B:$M,9,FALSE()),"")) -> 1 | G18: =SUMIFS($J19:J$44,$I19:I$44,"<>x",$I19:I$44,"<>o",$J19:J$44,">0")/Aggregate!$J$1 -> 0 | H18: {=IFERROR(INDEX(ECR!$K:$K,MATCH(DraftSheet!$C18,ECR!$C:$C,0)),"ND")} -> 103 | J18: =VLOOKUP(C18,Aggregate!B:J,9,FALSE()) -> -4.150412 | L18: =IFERROR(VLOOKUP(DraftSheet!$M18,Aggregate!$P:$AA,11,FALSE()),"") -> 3 | M18: =Aggregate!P18 -> Josh Jacobs | N18: =VLOOKUP(DraftSheet!$M18,Aggregate!P:AA,4,FALSE()) -> GB/11 | O18: =IFERROR(VLOOKUP(DraftSheet!$M18,Aggregate!$P:$AA,8,FALSE()),"") -> 173.90941 | P18: =IF(Scoring!$K$6="Auction",IFERROR(VLOOKUP(DraftSheet!$M18,Aggregate!$P:$AA,10,FALSE()),""),IFERROR(VLOOKUP(DraftSheet!$M18,Aggregate!$P:$AA,9,FALSE()),"")) -> 26.028091 | Q18: =SUMIFS($T19:T$84,$S19:S$84,"<>x",$S19:S$84,"<>o",$T19:T$84,">0")/Aggregate!$X$1 -> 0.46956786 | R18: {=IFERROR(INDEX(ECR!$K:$K,MATCH(DraftSheet!$M18,ECR!$C:$C,0)),"ND")} -> 38 | T18: =VLOOKUP(M18,Aggregate!P:X,9,FALSE()) -> 95.518523 | V18: =IFERROR(VLOOKUP(DraftSheet!$W18,Aggregate!$AD:$AO,11,FALSE()),"") -> 3 | W18: =Aggregate!AD17 -> Zay Flowers | X18: =VLOOKUP(DraftSheet!$W18,Aggregate!AD:AO,4,FALSE()) -> BAL/13 | Y18: =IFERROR(VLOOKUP(DraftSheet!$W18,Aggregate!$AD:$AO,8,FALSE()),"") -> 157.29494 | Z18: =IF(Scoring!$K$6="Auction",IFERROR(VLOOKUP(DraftSheet!$W18,Aggregate!$AD:$AO,10,FALSE()),""),IFERROR(VLOOKUP(DraftSheet!$W18,Aggregate!$AD:$AO,9,FALSE()),"")) -> 20.854566 | AA18: =SUMIFS($AD19:AD$84,$AC19:AC$84,"<>x",$AC19:AC$84,"<>o",$AD19:AD$84,">0")/Aggregate!$AL$1 -> 0.5046362 | AB18: {=IFERROR(INDEX(ECR!$K:$K,MATCH(DraftSheet!$W18,ECR!$C:$C,0)),"ND")} -> 31 | AD18: =VLOOKUP(W18,Aggregate!AD:AL,9,FALSE()) -> 75.774011
B19: =IFERROR(VLOOKUP(DraftSheet!$C19,Aggregate!$B:$M,11,FALSE()),"") -> 4 | C19: =Aggregate!B17 -> Matthew Stafford | D19: =VLOOKUP(DraftSheet!$C19,Aggregate!B:M,4,FALSE()) -> LAR/11 | E19: =IFERROR(VLOOKUP(DraftSheet!$C19,Aggregate!$B:$M,8,FALSE()),"") -> 218.85306 | F19: =IF(Scoring!$K$6="Auction",IFERROR(VLOOKUP(DraftSheet!$C19,Aggregate!$B:$M,10,FALSE()),""),IFERROR(VLOOKUP(DraftSheet!$C19,Aggregate!$B:$M,9,FALSE()),"")) -> 1 | G19: =SUMIFS($J20:J$44,$I20:I$44,"<>x",$I20:I$44,"<>o",$J20:J$44,">0")/Aggregate!$J$1 -> 0 | H19: {=IFERROR(INDEX(ECR!$K:$K,MATCH(DraftSheet!$C19,ECR!$C:$C,0)),"ND")} -> 110 | J19: =VLOOKUP(C19,Aggregate!B:J,9,FALSE()) -> -2.7937438 | L19: =IFERROR(VLOOKUP(DraftSheet!$M19,Aggregate!$P:$AA,11,FALSE()),"") -> 4 | M19: =Aggregate!P15 -> Kyren Williams | N19: =VLOOKUP(DraftSheet!$M19,Aggregate!P:AA,4,FALSE()) -> LAR/11 | O19: =IFERROR(VLOOKUP(DraftSheet!$M19,Aggregate!$P:$AA,8,FALSE()),"") -> 172.45647 | P19: =IF(Scoring!$K$6="Auction",IFERROR(VLOOKUP(DraftSheet!$M19,Aggregate!$P:$AA,10,FALSE()),""),IFERROR(VLOOKUP(DraftSheet!$M19,Aggregate!$P:$AA,9,FALSE()),"")) -> 25.647386 | Q19: =SUMIFS($T20:T$84,$S20:S$84,"<>x",$S20:S$84,"<>o",$T20:T$84,">0")/Aggregate!$X$1 -> 0.4403025 | R19: {=IFERROR(INDEX(ECR!$K:$K,MATCH(DraftSheet!$M19,ECR!$C:$C,0)),"ND")} -> 32 | T19: =VLOOKUP(M19,Aggregate!P:X,9,FALSE()) -> 94.065581 | V19: =IFERROR(VLOOKUP(DraftSheet!$W19,Aggregate!$AD:$AO,11,FALSE()),"") -> 3 | W19: =Aggregate!AD16 -> DeVonta Smith | X19: =VLOOKUP(DraftSheet!$W19,Aggregate!AD:AO,4,FALSE()) -> PHI/10 | Y19: =IFERROR(VLOOKUP(DraftSheet!$W19,Aggregate!$AD:$AO,8,FALSE()),"") -> 154.09493 | Z19: =IF(Scoring!$K$6="Auction",IFERROR(VLOOKUP(DraftSheet!$W19,Aggregate!$AD:$AO,10,FALSE()),""),IFERROR(VLOOKUP(DraftSheet!$W19,Aggregate!$AD:$AO,9,FALSE()),"")) -> 20.016088 | AA19: =SUMIFS($AD20:AD$84,$AC20:AC$84,"<>x",$AC20:AC$84,"<>o",$AD20:AD$84,">0")/Aggregate!$AL$1 -> 0.48096641 | AB19: {=IFERROR(INDEX(ECR!$K:$K,MATCH(DraftSheet!$W19,ECR!$C:$C,0)),"ND")} -> 30 | AD19: =VLOOKUP(W19,Aggregate!AD:AL,9,FALSE()) -> 72.574
B20: =IFERROR(VLOOKUP(DraftSheet!$C20,Aggregate!$B:$M,11,FALSE()),"") -> 5 | C20: =Aggregate!B18 -> Jared Goff | D20: =VLOOKUP(DraftSheet!$C20,Aggregate!B:M,4,FALSE()) -> DET/6 | E20: =IFERROR(VLOOKUP(DraftSheet!$C20,Aggregate!$B:$M,8,FALSE()),"") -> 205.68354 | F20: =IF(Scoring!$K$6="Auction",IFERROR(VLOOKUP(DraftSheet!$C20,Aggregate!$B:$M,10,FALSE()),""),IFERROR(VLOOKUP(DraftSheet!$C20,Aggregate!$B:$M,9,FALSE()),"")) -> 1 | G20: =SUMIFS($J21:J$44,$I21:I$44,"<>x",$I21:I$44,"<>o",$J21:J$44,">0")/Aggregate!$J$1 -> 0 | H20: {=IFERROR(INDEX(ECR!$K:$K,MATCH(DraftSheet!$C20,ECR!$C:$C,0)),"ND")} -> 112 | J20: =VLOOKUP(C20,Aggregate!B:J,9,FALSE()) -> -15.963263 | L20: =IFERROR(VLOOKUP(DraftSheet!$M20,Aggregate!$P:$AA,11,FALSE()),"") -> 4 | M20: =Aggregate!P17 -> Breece Hall | N20: =VLOOKUP(DraftSheet!$M20,Aggregate!P:AA,4,FALSE()) -> NYJ/13 | O20: =IFERROR(VLOOKUP(DraftSheet!$M20,Aggregate!$P:$AA,8,FALSE()),"") -> 169.89471 | P20: =IF(Scoring!$K$6="Auction",IFERROR(VLOOKUP(DraftSheet!$M20,Aggregate!$P:$AA,10,FALSE()),""),IFERROR(VLOOKUP(DraftSheet!$M20,Aggregate!$P:$AA,9,FALSE()),"")) -> 24.976144 | Q20: =SUMIFS($T21:T$84,$S21:S$84,"<>x",$S21:S$84,"<>o",$T21:T$84,">0")/Aggregate!$X$1 -> 0.41183414 | R20: {=IFERROR(INDEX(ECR!$K:$K,MATCH(DraftSheet!$M20,ECR!$C:$C,0)),"ND")} -> 36 | T20: =VLOOKUP(M20,Aggregate!P:X,9,FALSE()) -> 91.503817 | V20: =IFERROR(VLOOKUP(DraftSheet!$W20,Aggregate!$AD:$AO,11,FALSE()),"") -> 3 | W20: =Aggregate!AD19 -> Tetairoa McMillan | X20: =VLOOKUP(DraftSheet!$W20,Aggregate!AD:AO,4,FALSE()) -> CAR/5 | Y20: =IFERROR(VLOOKUP(DraftSheet!$W20,Aggregate!$AD:$AO,8,FALSE()),"") -> 150.77059 | Z20: =IF(Scoring!$K$6="Auction",IFERROR(VLOOKUP(DraftSheet!$W20,Aggregate!$AD:$AO,10,FALSE()),""),IFERROR(VLOOKUP(DraftSheet!$W20,Aggregate!$AD:$AO,9,FALSE()),"")) -> 19.145035 | AA20: =SUMIFS($AD21:AD$84,$AC21:AC$84,"<>x",$AC21:AC$84,"<>o",$AD21:AD$84,">0")/Aggregate!$AL$1 -> 0.45838084 | AB20: {=IFERROR(INDEX(ECR!$K:$K,MATCH(DraftSheet!$W20,ECR!$C:$C,0)),"ND")} -> 35 | AD20: =VLOOKUP(W20,Aggregate!AD:AL,9,FALSE()) -> 69.249667
B21: =IFERROR(VLOOKUP(DraftSheet!$C21,Aggregate!$B:$M,11,FALSE()),"") -> 5 | C21: =Aggregate!B19 -> Baker Mayfield | D21: =VLOOKUP(DraftSheet!$C21,Aggregate!B:M,4,FALSE()) -> TB/10 | E21: =IFERROR(VLOOKUP(DraftSheet!$C21,Aggregate!$B:$M,8,FALSE()),"") -> 196.40535 | F21: =IF(Scoring!$K$6="Auction",IFERROR(VLOOKUP(DraftSheet!$C21,Aggregate!$B:$M,10,FALSE()),""),IFERROR(VLOOKUP(DraftSheet!$C21,Aggregate!$B:$M,9,FALSE()),"")) -> 1 | G21: =SUMIFS($J22:J$44,$I22:I$44,"<>x",$I22:I$44,"<>o",$J22:J$44,">0")/Aggregate!$J$1 -> 0 | H21: {=IFERROR(INDEX(ECR!$K:$K,MATCH(DraftSheet!$C21,ECR!$C:$C,0)),"ND")} -> 120 | J21: =VLOOKUP(C21,Aggregate!B:J,9,FALSE()) -> -25.241452 | L21: =IFERROR(VLOOKUP(DraftSheet!$M21,Aggregate!$P:$AA,11,FALSE()),"") -> 4 | M21: =Aggregate!P16 -> Javonte Williams | N21: =VLOOKUP(DraftSheet!$M21,Aggregate!P:AA,4,FALSE()) -> DAL/14 | O21: =IFERROR(VLOOKUP(DraftSheet!$M21,Aggregate!$P:$AA,8,FALSE()),"") -> 169.56779 | P21: =IF(Scoring!$K$6="Auction",IFERROR(VLOOKUP(DraftSheet!$M21,Aggregate!$P:$AA,10,FALSE()),""),IFERROR(VLOOKUP(DraftSheet!$M21,Aggregate!$P:$AA,9,FALSE()),"")) -> 24.890485 | Q21: =SUMIFS($T22:T$84,$S22:S$84,"<>x",$S22:S$84,"<>o",$T22:T$84,">0")/Aggregate!$X$1 -> 0.38346749 | R21: {=IFERROR(INDEX(ECR!$K:$K,MATCH(DraftSheet!$M21,ECR!$C:$C,0)),"ND")} -> 34 | T21: =VLOOKUP(M21,Aggregate!P:X,9,FALSE()) -> 91.176905 | V21: =IFERROR(VLOOKUP(DraftSheet!$W21,Aggregate!$AD:$AO,11,FALSE()),"") -> 3 | W21: =Aggregate!AD20 -> Garrett Wilson | X21: =VLOOKUP(DraftSheet!$W21,Aggregate!AD:AO,4,FALSE()) -> NYJ/13 | Y21: =IFERROR(VLOOKUP(DraftSheet!$W21,Aggregate!$AD:$AO,8,FALSE()),"") -> 149.87406 | Z21: =IF(Scoring!$K$6="Auction",IFERROR(VLOOKUP(DraftSheet!$W21,Aggregate!$AD:$AO,10,FALSE()),""),IFERROR(VLOOKUP(DraftSheet!$W21,Aggregate!$AD:$AO,9,FALSE()),"")) -> 18.910122 | AA21: =SUMIFS($AD22:AD$84,$AC22:AC$84,"<>x",$AC22:AC$84,"<>o",$AD22:AD$84,">0")/Aggregate!$AL$1 -> 0.43608767 | AB21: {=IFERROR(INDEX(ECR!$K:$K,MATCH(DraftSheet!$W21,ECR!$C:$C,0)),"ND")} -> 39 | AD21: =VLOOKUP(W21,Aggregate!AD:AL,9,FALSE()) -> 68.353134
B22: =IFERROR(VLOOKUP(DraftSheet!$C22,Aggregate!$B:$M,11,FALSE()),"") -> 6 | C22: =Aggregate!B20 -> Kyler Murray | D22: =VLOOKUP(DraftSheet!$C22,Aggregate!B:M,4,FALSE()) -> MIN/6 | E22: =IFERROR(VLOOKUP(DraftSheet!$C22,Aggregate!$B:$M,8,FALSE()),"") -> 192.78124 | F22: =IF(Scoring!$K$6="Auction",IFERROR(VLOOKUP(DraftSheet!$C22,Aggregate!$B:$M,10,FALSE()),""),IFERROR(VLOOKUP(DraftSheet!$C22,Aggregate!$B:$M,9,FALSE()),"")) -> 1 | G22: =SUMIFS($J23:J$44,$I23:I$44,"<>x",$I23:I$44,"<>o",$J23:J$44,">0")/Aggregate!$J$1 -> 0 | H22: {=IFERROR(INDEX(ECR!$K:$K,MATCH(DraftSheet!$C22,ECR!$C:$C,0)),"ND")} -> 122 | J22: =VLOOKUP(C22,Aggregate!B:J,9,FALSE()) -> -28.865568 | L22: =IFERROR(VLOOKUP(DraftSheet!$M22,Aggregate!$P:$AA,11,FALSE()),"") -> 4 | M22: =Aggregate!P20 -> Travis Etienne Jr. | N22: =VLOOKUP(DraftSheet!$M22,Aggregate!P:AA,4,FALSE()) -> NO/8 | O22: =IFERROR(VLOOKUP(DraftSheet!$M22,Aggregate!$P:$AA,8,FALSE()),"") -> 163.64132 | P22: =IF(Scoring!$K$6="Auction",IFERROR(VLOOKUP(DraftSheet!$M22,Aggregate!$P:$AA,10,FALSE()),""),IFERROR(VLOOKUP(DraftSheet!$M22,Aggregate!$P:$AA,9,FALSE()),"")) -> 23.337611 | Q22: =SUMIFS($T23:T$84,$S23:S$84,"<>x",$S23:S$84,"<>o",$T23:T$84,">0")/Aggregate!$X$1 -> 0.35694467 | R22: {=IFERROR(INDEX(ECR!$K:$K,MATCH(DraftSheet!$M22,ECR!$C:$C,0)),"ND")} -> 46 | T22: =VLOOKUP(M22,Aggregate!P:X,9,FALSE()) -> 85.250434 | V22: =IFERROR(VLOOKUP(DraftSheet!$W22,Aggregate!$AD:$AO,11,FALSE()),"") -> 3 | W22: =Aggregate!AD18 -> Tee Higgins | X22: =VLOOKUP(DraftSheet!$W22,Aggregate!AD:AO,4,FALSE()) -> CIN/6 | Y22: =IFERROR(VLOOKUP(DraftSheet!$W22,Aggregate!$AD:$AO,8,FALSE()),"") -> 148.02104 | Z22: =IF(Scoring!$K$6="Auction",IFERROR(VLOOKUP(DraftSheet!$W22,Aggregate!$AD:$AO,10,FALSE()),""),IFERROR(VLOOKUP(DraftSheet!$W22,Aggregate!$AD:$AO,9,FALSE()),"")) -> 18.424587 | AA22: =SUMIFS($AD23:AD$84,$AC23:AC$84,"<>x",$AC23:AC$84,"<>o",$AD23:AD$84,">0")/Aggregate!$AL$1 -> 0.41439886 | AB22: {=IFERROR(INDEX(ECR!$K:$K,MATCH(DraftSheet!$W22,ECR!$C:$C,0)),"ND")} -> 33 | AD22: =VLOOKUP(W22,Aggregate!AD:AL,9,FALSE()) -> 66.500112
B23: =IFERROR(VLOOKUP(DraftSheet!$C23,Aggregate!$B:$M,11,FALSE()),"") -> 6 | C23: =Aggregate!B22 -> Tyler Shough | D23: =VLOOKUP(DraftSheet!$C23,Aggregate!B:M,4,FALSE()) -> NO/8 | E23: =IFERROR(VLOOKUP(DraftSheet!$C23,Aggregate!$B:$M,8,FALSE()),"") -> 185.27069 | F23: =IF(Scoring!$K$6="Auction",IFERROR(VLOOKUP(DraftSheet!$C23,Aggregate!$B:$M,10,FALSE()),""),IFERROR(VLOOKUP(DraftSheet!$C23,Aggregate!$B:$M,9,FALSE()),"")) -> 1 | G23: =SUMIFS($J24:J$44,$I24:I$44,"<>x",$I24:I$44,"<>o",$J24:J$44,">0")/Aggregate!$J$1 -> 0 | H23: {=IFERROR(INDEX(ECR!$K:$K,MATCH(DraftSheet!$C23,ECR!$C:$C,0)),"ND")} -> 127 | J23: =VLOOKUP(C23,Aggregate!B:J,9,FALSE()) -> -36.37612 | L23: =IFERROR(VLOOKUP(DraftSheet!$M23,Aggregate!$P:$AA,11,FALSE()),"") -> 4 | M23: =Aggregate!P22 -> Cam Skattebo | N23: =VLOOKUP(DraftSheet!$M23,Aggregate!P:AA,4,FALSE()) -> NYG/8 | O23: =IFERROR(VLOOKUP(DraftSheet!$M23,Aggregate!$P:$AA,8,FALSE()),"") -> 161.73338 | P23: =IF(Scoring!$K$6="Auction",IFERROR(VLOOKUP(DraftSheet!$M23,Aggregate!$P:$AA,10,FALSE()),""),IFERROR(VLOOKUP(DraftSheet!$M23,Aggregate!$P:$AA,9,FALSE()),"")) -> 22.837686 | Q23: =SUMIFS($T24:T$84,$S24:S$84,"<>x",$S24:S$84,"<>o",$T24:T$84,">0")/Aggregate!$X$1 -> 0.33101543 | R23: {=IFERROR(INDEX(ECR!$K:$K,MATCH(DraftSheet!$M23,ECR!$C:$C,0)),"ND")} -> 52 | T23: =VLOOKUP(M23,Aggregate!P:X,9,FALSE()) -> 83.342493 | V23: =IFERROR(VLOOKUP(DraftSheet!$W23,Aggregate!$AD:$AO,11,FALSE()),"") -> 3 | W23: =Aggregate!AD23 -> Emeka Egbuka | X23: =VLOOKUP(DraftSheet!$W23,Aggregate!AD:AO,4,FALSE()) -> TB/10 | Y23: =IFERROR(VLOOKUP(DraftSheet!$W23,Aggregate!$AD:$AO,8,FALSE()),"") -> 144.3515 | Z23: =IF(Scoring!$K$6="Auction",IFERROR(VLOOKUP(DraftSheet!$W23,Aggregate!$AD:$AO,10,FALSE()),""),IFERROR(VLOOKUP(DraftSheet!$W23,Aggregate!$AD:$AO,9,FALSE()),"")) -> 17.463082 | AA23: =SUMIFS($AD24:AD$84,$AC24:AC$84,"<>x",$AC24:AC$84,"<>o",$AD24:AD$84,">0")/Aggregate!$AL$1 -> 0.39390686 | AB23: {=IFERROR(INDEX(ECR!$K:$K,MATCH(DraftSheet!$W23,ECR!$C:$C,0)),"ND")} -> 43 | AD23: =VLOOKUP(W23,Aggregate!AD:AL,9,FALSE()) -> 62.830574
B24: =IFERROR(VLOOKUP(DraftSheet!$C24,Aggregate!$B:$M,11,FALSE()),"") -> 6 | C24: =Aggregate!B21 -> Jordan Love | D24: =VLOOKUP(DraftSheet!$C24,Aggregate!B:M,4,FALSE()) -> GB/11 | E24: =IFERROR(VLOOKUP(DraftSheet!$C24,Aggregate!$B:$M,8,FALSE()),"") -> 184.55501 | F24: =IF(Scoring!$K$6="Auction",IFERROR(VLOOKUP(DraftSheet!$C24,Aggregate!$B:$M,10,FALSE()),""),IFERROR(VLOOKUP(DraftSheet!$C24,Aggregate!$B:$M,9,FALSE()),"")) -> 1 | G24: =SUMIFS($J25:J$44,$I25:I$44,"<>x",$I25:I$44,"<>o",$J25:J$44,">0")/Aggregate!$J$1 -> 0 | H24: {=IFERROR(INDEX(ECR!$K:$K,MATCH(DraftSheet!$C24,ECR!$C:$C,0)),"ND")} -> 123 | J24: =VLOOKUP(C24,Aggregate!B:J,9,FALSE()) -> -37.091794 | L24: =IFERROR(VLOOKUP(DraftSheet!$M24,Aggregate!$P:$AA,11,FALSE()),"") -> 4 | M24: =Aggregate!P21 -> D'Andre Swift | N24: =VLOOKUP(DraftSheet!$M24,Aggregate!P:AA,4,FALSE()) -> CHI/10 | O24: =IFERROR(VLOOKUP(DraftSheet!$M24,Aggregate!$P:$AA,8,FALSE()),"") -> 158.25015 | P24: =IF(Scoring!$K$6="Auction",IFERROR(VLOOKUP(DraftSheet!$M24,Aggregate!$P:$AA,10,FALSE()),""),IFERROR(VLOOKUP(DraftSheet!$M24,Aggregate!$P:$AA,9,FALSE()),"")) -> 21.924997 | Q24: =SUMIFS($T25:T$84,$S25:S$84,"<>x",$S25:S$84,"<>o",$T25:T$84,">0")/Aggregate!$X$1 -> 0.30616989 | R24: {=IFERROR(INDEX(ECR!$K:$K,MATCH(DraftSheet!$M24,ECR!$C:$C,0)),"ND")} -> 49 | T24: =VLOOKUP(M24,Aggregate!P:X,9,FALSE()) -> 79.859258 | V24: =IFERROR(VLOOKUP(DraftSheet!$W24,Aggregate!$AD:$AO,11,FALSE()),"") -> 3 | W24: =Aggregate!AD25 -> Davante Adams | X24: =VLOOKUP(DraftSheet!$W24,Aggregate!AD:AO,4,FALSE()) -> LAR/11 | Y24: =IFERROR(VLOOKUP(DraftSheet!$W24,Aggregate!$AD:$AO,8,FALSE()),"") -> 140.60684 | Z24: =IF(Scoring!$K$6="Auction",IFERROR(VLOOKUP(DraftSheet!$W24,Aggregate!$AD:$AO,10,FALSE()),""),IFERROR(VLOOKUP(DraftSheet!$W24,Aggregate!$AD:$AO,9,FALSE()),"")) -> 16.481893 | AA24: =SUMIFS($AD25:AD$84,$AC25:AC$84,"<>x",$AC25:AC$84,"<>o",$AD25:AD$84,">0")/Aggregate!$AL$1 -> 0.37463616 | AB24: {=IFERROR(INDEX(ECR!$K:$K,MATCH(DraftSheet!$W24,ECR!$C:$C,0)),"ND")} -> 48 | AD24: =VLOOKUP(W24,Aggregate!AD:AL,9,FALSE()) -> 59.085912
B25: =IFERROR(VLOOKUP(DraftSheet!$C25,Aggregate!$B:$M,11,FALSE()),"") -> 7 | C25: =Aggregate!B23 -> Malik Willis | D25: =VLOOKUP(DraftSheet!$C25,Aggregate!B:M,4,FALSE()) -> MIA/6 | E25: =IFERROR(VLOOKUP(DraftSheet!$C25,Aggregate!$B:$M,8,FALSE()),"") -> 176.08508 | F25: =IF(Scoring!$K$6="Auction",IFERROR(VLOOKUP(DraftSheet!$C25,Aggregate!$B:$M,10,FALSE()),""),IFERROR(VLOOKUP(DraftSheet!$C25,Aggregate!$B:$M,9,FALSE()),"")) -> 1 | G25: =SUMIFS($J26:J$44,$I26:I$44,"<>x",$I26:I$44,"<>o",$J26:J$44,">0")/Aggregate!$J$1 -> 0 | H25: {=IFERROR(INDEX(ECR!$K:$K,MATCH(DraftSheet!$C25,ECR!$C:$C,0)),"ND")} -> 137 | J25: =VLOOKUP(C25,Aggregate!B:J,9,FALSE()) -> -45.561722 | L25: =IFERROR(VLOOKUP(DraftSheet!$M25,Aggregate!$P:$AA,11,FALSE()),"") -> 4 | M25: =Aggregate!P23 -> Bucky Irving | N25: =VLOOKUP(DraftSheet!$M25,Aggregate!P:AA,4,FALSE()) -> TB/10 | O25: =IFERROR(VLOOKUP(DraftSheet!$M25,Aggregate!$P:$AA,8,FALSE()),"") -> 156.50471 | P25: =IF(Scoring!$K$6="Auction",IFERROR(VLOOKUP(DraftSheet!$M25,Aggregate!$P:$AA,10,FALSE()),""),IFERROR(VLOOKUP(DraftSheet!$M25,Aggregate!$P:$AA,9,FALSE()),"")) -> 21.46765 | Q25: =SUMIFS($T26:T$84,$S26:S$84,"<>x",$S26:S$84,"<>o",$T26:T$84,">0")/Aggregate!$X$1 -> 0.28186738 | R25: {=IFERROR(INDEX(ECR!$K:$K,MATCH(DraftSheet!$M25,ECR!$C:$C,0)),"ND")} -> 55 | T25: =VLOOKUP(M25,Aggregate!P:X,9,FALSE()) -> 78.113817 | V25: =IFERROR(VLOOKUP(DraftSheet!$W25,Aggregate!$AD:$AO,11,FALSE()),"") -> 3 | W25: =Aggregate!AD22 -> Ladd McConkey | X25: =VLOOKUP(DraftSheet!$W25,Aggregate!AD:AO,4,FALSE()) -> LAC/7 | Y25: =IFERROR(VLOOKUP(DraftSheet!$W25,Aggregate!$AD:$AO,8,FALSE()),"") -> 139.71119 | Z25: =IF(Scoring!$K$6="Auction",IFERROR(VLOOKUP(DraftSheet!$W25,Aggregate!$AD:$AO,10,FALSE()),""),IFERROR(VLOOKUP(DraftSheet!$W25,Aggregate!$AD:$AO,9,FALSE()),"")) -> 16.247211 | AA25: =SUMIFS($AD26:AD$84,$AC26:AC$84,"<>x",$AC26:AC$84,"<>o",$AD26:AD$84,">0")/Aggregate!$AL$1 -> 0.35565759 | AB25: {=IFERROR(INDEX(ECR!$K:$K,MATCH(DraftSheet!$W25,ECR!$C:$C,0)),"ND")} -> 41 | AD25: =VLOOKUP(W25,Aggregate!AD:AL,9,FALSE()) -> 58.190258
B26: =IFERROR(VLOOKUP(DraftSheet!$C26,Aggregate!$B:$M,11,FALSE()),"") -> 7 | C26: =Aggregate!B27 -> Daniel Jones | D26: =VLOOKUP(DraftSheet!$C26,Aggregate!B:M,4,FALSE()) -> IND/13 | E26: =IFERROR(VLOOKUP(DraftSheet!$C26,Aggregate!$B:$M,8,FALSE()),"") -> 177.24875 | F26: =IF(Scoring!$K$6="Auction",IFERROR(VLOOKUP(DraftSheet!$C26,Aggregate!$B:$M,10,FALSE()),""),IFERROR(VLOOKUP(DraftSheet!$C26,Aggregate!$B:$M,9,FALSE()),"")) -> 1 | G26: =SUMIFS($J27:J$44,$I27:I$44,"<>x",$I27:I$44,"<>o",$J27:J$44,">0")/Aggregate!$J$1 -> 0 | H26: {=IFERROR(INDEX(ECR!$K:$K,MATCH(DraftSheet!$C26,ECR!$C:$C,0)),"ND")} -> 157 | J26: =VLOOKUP(C26,Aggregate!B:J,9,FALSE()) -> -44.398053 | L26: =IFERROR(VLOOKUP(DraftSheet!$M26,Aggregate!$P:$AA,11,FALSE()),"") -> 4 | M26: =Aggregate!P24 -> Quinshon Judkins | N26: =VLOOKUP(DraftSheet!$M26,Aggregate!P:AA,4,FALSE()) -> CLE/11 | O26: =IFERROR(VLOOKUP(DraftSheet!$M26,Aggregate!$P:$AA,8,FALSE()),"") -> 152.89529 | P26: =IF(Scoring!$K$6="Auction",IFERROR(VLOOKUP(DraftSheet!$M26,Aggregate!$P:$AA,10,FALSE()),""),IFERROR(VLOOKUP(DraftSheet!$M26,Aggregate!$P:$AA,9,FALSE()),"")) -> 20.5219 | Q26: =SUMIFS($T27:T$84,$S27:S$84,"<>x",$S27:S$84,"<>o",$T27:T$84,">0")/Aggregate!$X$1 -> 0.25868783 | R26: {=IFERROR(INDEX(ECR!$K:$K,MATCH(DraftSheet!$M26,ECR!$C:$C,0)),"ND")} -> 56 | T26: =VLOOKUP(M26,Aggregate!P:X,9,FALSE()) -> 74.504405 | V26: =IFERROR(VLOOKUP(DraftSheet!$W26,Aggregate!$AD:$AO,11,FALSE()),"") -> 3 | W26: =Aggregate!AD24 -> Terry McLaurin | X26: =VLOOKUP(DraftSheet!$W26,Aggregate!AD:AO,4,FALSE()) -> WAS/7 | Y26: =IFERROR(VLOOKUP(DraftSheet!$W26,Aggregate!$AD:$AO,8,FALSE()),"") -> 137.38664 | Z26: =IF(Scoring!$K$6="Auction",IFERROR(VLOOKUP(DraftSheet!$W26,Aggregate!$AD:$AO,10,FALSE()),""),IFERROR(VLOOKUP(DraftSheet!$W26,Aggregate!$AD:$AO,9,FALSE()),"")) -> 15.638125 | AA26: =SUMIFS($AD27:AD$84,$AC27:AC$84,"<>x",$AC27:AC$84,"<>o",$AD27:AD$84,">0")/Aggregate!$AL$1 -> 0.33743715 | AB26: {=IFERROR(INDEX(ECR!$K:$K,MATCH(DraftSheet!$W26,ECR!$C:$C,0)),"ND")} -> 47 | AD26: =VLOOKUP(W26,Aggregate!AD:AL,9,FALSE()) -> 55.86571
B27: =IFERROR(VLOOKUP(DraftSheet!$C27,Aggregate!$B:$M,11,FALSE()),"") -> 7 | C27: =Aggregate!B24 -> Sam Darnold | D27: =VLOOKUP(DraftSheet!$C27,Aggregate!B:M,4,FALSE()) -> SEA/11 | E27: =IFERROR(VLOOKUP(DraftSheet!$C27,Aggregate!$B:$M,8,FALSE()),"") -> 173.38499 | F27: =IF(Scoring!$K$6="Auction",IFERROR(VLOOKUP(DraftSheet!$C27,Aggregate!$B:$M,10,FALSE()),""),IFERROR(VLOOKUP(DraftSheet!$C27,Aggregate!$B:$M,9,FALSE()),"")) -> 1 | G27: =SUMIFS($J28:J$44,$I28:I$44,"<>x",$I28:I$44,"<>o",$J28:J$44,">0")/Aggregate!$J$1 -> 0 | H27: {=IFERROR(INDEX(ECR!$K:$K,MATCH(DraftSheet!$C27,ECR!$C:$C,0)),"ND")} -> 142 | J27: =VLOOKUP(C27,Aggregate!B:J,9,FALSE()) -> -48.261815 | L27: =IFERROR(VLOOKUP(DraftSheet!$M27,Aggregate!$P:$AA,11,FALSE()),"") -> 5 | M27: =Aggregate!P26 -> Bhayshul Tuten | N27: =VLOOKUP(DraftSheet!$M27,Aggregate!P:AA,4,FALSE()) -> JAC/7 | O27: =IFERROR(VLOOKUP(DraftSheet!$M27,Aggregate!$P:$AA,8,FALSE()),"") -> 147.64936 | P27: =IF(Scoring!$K$6="Auction",IFERROR(VLOOKUP(DraftSheet!$M27,Aggregate!$P:$AA,10,FALSE()),""),IFERROR(VLOOKUP(DraftSheet!$M27,Aggregate!$P:$AA,9,FALSE()),"")) -> 19.147342 | Q27: =SUMIFS($T28:T$84,$S28:S$84,"<>x",$S28:S$84,"<>o",$T28:T$84,">0")/Aggregate!$X$1 -> 0.23714036 | R27: {=IFERROR(INDEX(ECR!$K:$K,MATCH(DraftSheet!$M27,ECR!$C:$C,0)),"ND")} -> 64 | T27: =VLOOKUP(M27,Aggregate!P:X,9,FALSE()) -> 69.258472 | V27: =IFERROR(VLOOKUP(DraftSheet!$W27,Aggregate!$AD:$AO,11,FALSE()),"") -> 3 | W27: =Aggregate!AD21 -> Jaylen Waddle | X27: =VLOOKUP(DraftSheet!$W27,Aggregate!AD:AO,4,FALSE()) -> DEN/10 | Y27: =IFERROR(VLOOKUP(DraftSheet!$W27,Aggregate!$AD:$AO,8,FALSE()),"") -> 136.69467 | Z27: =IF(Scoring!$K$6="Auction",IFERROR(VLOOKUP(DraftSheet!$W27,Aggregate!$AD:$AO,10,FALSE()),""),IFERROR(VLOOKUP(DraftSheet!$W27,Aggregate!$AD:$AO,9,FALSE()),"")) -> 15.456814 | AA27: =SUMIFS($AD28:AD$84,$AC28:AC$84,"<>x",$AC28:AC$84,"<>o",$AD28:AD$84,">0")/Aggregate!$AL$1 -> 0.31944241 | AB27: {=IFERROR(INDEX(ECR!$K:$K,MATCH(DraftSheet!$W27,ECR!$C:$C,0)),"ND")} -> 40 | AD27: =VLOOKUP(W27,Aggregate!AD:AL,9,FALSE()) -> 55.173744
B28: =IFERROR(VLOOKUP(DraftSheet!$C28,Aggregate!$B:$M,11,FALSE()),"") -> 7 | C28: =Aggregate!B25 -> C.J. Stroud | D28: =VLOOKUP(DraftSheet!$C28,Aggregate!B:M,4,FALSE()) -> HOU/8 | E28: =IFERROR(VLOOKUP(DraftSheet!$C28,Aggregate!$B:$M,8,FALSE()),"") -> 168.67489 | F28: =IF(Scoring!$K$6="Auction",IFERROR(VLOOKUP(DraftSheet!$C28,Aggregate!$B:$M,10,FALSE()),""),IFERROR(VLOOKUP(DraftSheet!$C28,Aggregate!$B:$M,9,FALSE()),"")) -> 1 | G28: =SUMIFS($J29:J$44,$I29:I$44,"<>x",$I29:I$44,"<>o",$J29:J$44,">0")/Aggregate!$J$1 -> 0 | H28: {=IFERROR(INDEX(ECR!$K:$K,MATCH(DraftSheet!$C28,ECR!$C:$C,0)),"ND")} -> 147 | J28: =VLOOKUP(C28,Aggregate!B:J,9,FALSE()) -> -52.971911 | L28: =IFERROR(VLOOKUP(DraftSheet!$M28,Aggregate!$P:$AA,11,FALSE()),"") -> 5 | M28: =Aggregate!P28 -> Jadarian Price | N28: =VLOOKUP(DraftSheet!$M28,Aggregate!P:AA,4,FALSE()) -> SEA/11 | O28: =IFERROR(VLOOKUP(DraftSheet!$M28,Aggregate!$P:$AA,8,FALSE()),"") -> 145.73356 | P28: =IF(Scoring!$K$6="Auction",IFERROR(VLOOKUP(DraftSheet!$M28,Aggregate!$P:$AA,10,FALSE()),""),IFERROR(VLOOKUP(DraftSheet!$M28,Aggregate!$P:$AA,9,FALSE()),"")) -> 18.645358 | Q28: =SUMIFS($T29:T$84,$S29:S$84,"<>x",$S29:S$84,"<>o",$T29:T$84,">0")/Aggregate!$X$1 -> 0.21618894 | R28: {=IFERROR(INDEX(ECR!$K:$K,MATCH(DraftSheet!$M28,ECR!$C:$C,0)),"ND")} -> 66 | T28: =VLOOKUP(M28,Aggregate!P:X,9,FALSE()) -> 67.342672 | V28: =IFERROR(VLOOKUP(DraftSheet!$W28,Aggregate!$AD:$AO,11,FALSE()),"") -> 3 | W28: =Aggregate!AD27 -> Jameson Williams | X28: =VLOOKUP(DraftSheet!$W28,Aggregate!AD:AO,4,FALSE()) -> DET/6 | Y28: =IFERROR(VLOOKUP(DraftSheet!$W28,Aggregate!$AD:$AO,8,FALSE()),"") -> 135.87723 | Z28: =IF(Scoring!$K$6="Auction",IFERROR(VLOOKUP(DraftSheet!$W28,Aggregate!$AD:$AO,10,FALSE()),""),IFERROR(VLOOKUP(DraftSheet!$W28,Aggregate!$AD:$AO,9,FALSE()),"")) -> 15.242625 | AA28: =SUMIFS($AD29:AD$84,$AC29:AC$84,"<>x",$AC29:AC$84,"<>o",$AD29:AD$84,">0")/Aggregate!$AL$1 -> 0.30171426 | AB28: {=IFERROR(INDEX(ECR!$K:$K,MATCH(DraftSheet!$W28,ECR!$C:$C,0)),"ND")} -> 54 | AD28: =VLOOKUP(W28,Aggregate!AD:AL,9,FALSE()) -> 54.356303
B29: =IFERROR(VLOOKUP(DraftSheet!$C29,Aggregate!$B:$M,11,FALSE()),"") -> 8 | C29: =Aggregate!B28 -> Bryce Young | D29: =VLOOKUP(DraftSheet!$C29,Aggregate!B:M,4,FALSE()) -> CAR/5 | E29: =IFERROR(VLOOKUP(DraftSheet!$C29,Aggregate!$B:$M,8,FALSE()),"") -> 161.97271 | F29: =IF(Scoring!$K$6="Auction",IFERROR(VLOOKUP(DraftSheet!$C29,Aggregate!$B:$M,10,FALSE()),""),IFERROR(VLOOKUP(DraftSheet!$C29,Aggregate!$B:$M,9,FALSE()),"")) -> 1 | G29: =SUMIFS($J30:J$44,$I30:I$44,"<>x",$I30:I$44,"<>o",$J30:J$44,">0")/Aggregate!$J$1 -> 0 | H29: {=IFERROR(INDEX(ECR!$K:$K,MATCH(DraftSheet!$C29,ECR!$C:$C,0)),"ND")} -> 172 | J29: =VLOOKUP(C29,Aggregate!B:J,9,FALSE()) -> -59.6741 | L29: =IFERROR(VLOOKUP(DraftSheet!$M29,Aggregate!$P:$AA,11,FALSE()),"") -> 5 | M29: =Aggregate!P25 -> David Montgomery | N29: =VLOOKUP(DraftSheet!$M29,Aggregate!P:AA,4,FALSE()) -> HOU/8 | O29: =IFERROR(VLOOKUP(DraftSheet!$M29,Aggregate!$P:$AA,8,FALSE()),"") -> 142.41194 | P29: =IF(Scoring!$K$6="Auction",IFERROR(VLOOKUP(DraftSheet!$M29,Aggregate!$P:$AA,10,FALSE()),""),IFERROR(VLOOKUP(DraftSheet!$M29,Aggregate!$P:$AA,9,FALSE()),"")) -> 17.775014 | Q29: =SUMIFS($T30:T$84,$S30:S$84,"<>x",$S30:S$84,"<>o",$T30:T$84,">0")/Aggregate!$X$1 -> 0.19627093 | R29: {=IFERROR(INDEX(ECR!$K:$K,MATCH(DraftSheet!$M29,ECR!$C:$C,0)),"ND")} -> 57 | T29: =VLOOKUP(M29,Aggregate!P:X,9,FALSE()) -> 64.021047 | V29: =IFERROR(VLOOKUP(DraftSheet!$W29,Aggregate!$AD:$AO,11,FALSE()),"") -> 4 | W29: =Aggregate!AD26 -> Luther Burden III | X29: =VLOOKUP(DraftSheet!$W29,Aggregate!AD:AO,4,FALSE()) -> CHI/10 | Y29: =IFERROR(VLOOKUP(DraftSheet!$W29,Aggregate!$AD:$AO,8,FALSE()),"") -> 131.05068 | Z29: =IF(Scoring!$K$6="Auction",IFERROR(VLOOKUP(DraftSheet!$W29,Aggregate!$AD:$AO,10,FALSE()),""),IFERROR(VLOOKUP(DraftSheet!$W29,Aggregate!$AD:$AO,9,FALSE()),"")) -> 13.977955 | AA29: =SUMIFS($AD30:AD$84,$AC30:AC$84,"<>x",$AC30:AC$84,"<>o",$AD30:AD$84,">0")/Aggregate!$AL$1 -> 0.28556028 | AB29: {=IFERROR(INDEX(ECR!$K:$K,MATCH(DraftSheet!$W29,ECR!$C:$C,0)),"ND")} -> 51 | AD29: =VLOOKUP(W29,Aggregate!AD:AL,9,FALSE()) -> 49.529751
